Workbook

Sheet HOME
B2: GENESIS HR MANAGEMENT SYSTEM
B3: Namibia · NamRA Compliant · Financial Year 2024/2025
B6: Dashboard | D6: Employees | F6: Payroll Engine
B7: Executive KPIs, headcount & payroll overview | D7: Master database — all staff records, bank details, contracts & rates | F7: NamRA-compliant payroll: hourly, overtime, night, holiday & monthly pay
B8: =HYPERLINK("#'DASH Dashboard'!A1","Open Dashboard") -> Open Dashboard | D8: =HYPERLINK("#'EMP Employees'!A1","Open Employees") -> Open Employees | F8: =HYPERLINK("#'PAY Payroll'!A1","Open Payroll") -> Open Payroll
B11: Payslip | D11: Leave Tracker | F11: Absence Log
B12: Individual payslip generator with PDF export | D12: Annual leave earned, taken & remaining balances | F12: Approved absence records by type & date
B13: =HYPERLINK("#'SLP Payslip'!A1","Open Payslip") -> Open Payslip | D13: =HYPERLINK("#'LVE Leave'!A1","Open Leave Tracker") -> Open Leave Tracker | F13: =HYPERLINK("#'ABS Absence Log'!A1","Open Absence Log") -> Open Absence Log
B16: Recruitment | D16: Settings | F16: Audit Log
B17: Pipeline: candidates, scores & conversion metrics | D17: PAYE brackets, SSC rates & lookup lists | F17: Change history: who changed what & when
B18: =HYPERLINK("#'REC Recruitment'!A1","Open Recruitment") -> Open Recruitment | D18: =HYPERLINK("#'SET Settings'!A1","Open Settings") -> Open Settings | F18: =HYPERLINK("#'AUDIT LOG'!A1","Open Audit Log") -> Open Audit Log
B21: Monthly History
B22: 12-month payroll history per employee
B23: =HYPERLINK("#'HIST Monthly History'!A1","Open Monthly History") -> Open Monthly History
B27: COLOUR LEGEND | Blue cells = Input (editable) | Black cells = Formula (protected)
B28: Genesis HR System v4.0 | Revised: June 2026 | Author: HR Administrator | NamRA Compliant

Sheet GUIDE
B2: GENESIS HR · QUICK GUIDE
B5: COLOUR LEGEND
B6: Blue cells | C6: You type here — editable input fields
B7: Grey cells | C7: Automatic formulas — protected, do not edit
B8: Red highlight | C8: Warning: hourly rate below legal minimum (N$18/hr)
B9: Amber highlight | C9: Warning: overtime exceeds legal limit (10h/week)
B11: HOW TO ADD AN EMPLOYEE
B12: 1 | C12: Go to EMP Employees sheet
B13: 2 | C13: Fill blue cells left to right. Emp ID format: UN01, UN02...
B14: 3 | C14: Choose Pay Type: Hourly or Monthly (dropdown)
B15: 4 | C15: Hourly staff → fill Hourly Rate. Monthly staff → fill Basic Monthly Salary
B16: 5 | C16: Age calculates automatically from Date of Birth
B18: HOW TO RUN PAYROLL
B19: 1 | C19: Go to PAY Payroll sheet
B20: 2 | C20: Pick Emp ID (dropdown) — Name, Pay Type, Rate auto-fill
B21: 3 | C21: Enter hours worked: Normal, Overtime, Night, Holiday, Sunday
B22: 4 | C22: All salaries, PAYE, SSC and Net Pay calculate automatically
B23: 5 | C23: Rates follow Labour Act 2007: OT 1.5x, Night +6%, Sunday 2x
B25: HOW TO GENERATE A PAYSLIP
B26: 1 | C26: Go to SLP Payslip sheet
B27: 2 | C27: Select Employee ID in cell D1 (dropdown)
B28: 3 | C28: Payslip fills automatically. Print or export to PDF
B30: LEGAL RATES (Labour Act 2007 — editable in SET Settings)
B31: Normal Overtime | C31: 1.5 × base rate (Sec. 29)
B32: Night Hours (20:00–07:00) | C32: base rate + 6% (Sec. 32)
B33: Sunday / Public Holiday | C33: 2.0 × base rate (Sec. 33)
B34: Minimum Wage 2026 | C34: N$18.00 per hour
B35: SSC | C35: 0.9% of pay, capped at N$81/month
B36: PAYE | C36: NamRA tax bands — auto-calculated from gross

Sheet DASH Dashboard
A1: GENESIS HR · EXECUTIVE DASHBOARD
A2: ="Real-time KPIs · Auto-Refreshing · Data as of: "&TEXT(TODAY(),"DD MMMM YYYY") -> Real-time KPIs · Auto-Refreshing · Data as of: 18 June 2026
A4: TOTAL HEADCOUNT | E4: MONTHLY PAYROLL (N$) | I4: GENDER RATIO (Female) | M4: AVG TENURE (YRS)
A5: =COUNTIF('EMP Employees'!U3:U52,"Active") -> 0 | E5: =IFERROR('PAY Payroll'!U54,0) -> 0 | I5: =IFERROR(TEXT(COUNTIF('EMP Employees'!E3:E52,"Female")/COUNTIF('EMP Employees'!U3:U52,"Active"),"0.0%"),"0.0%") -> 0.0% | M5: =IFERROR(ROUND(AVERAGEIF('EMP Employees'!U3:U52,"Active",'EMP Employees'!V3:V52)/12,1),0) -> 0
A18: CONTRACTS EXPIRING IN THE NEXT 30 DAYS
A19: Emp ID | B19: Name | C19: Department | D19: Position | E19: Contract End Date | F19: Days Remaining
F20: =IFERROR(E20-TODAY(),"") -> -46191
F21: =IFERROR(E21-TODAY(),"") -> -46191
A22: Executive | B22: =COUNTIF('EMP Employees'!$M$3:$M$52,A22) -> 0 | E22: =COUNTIFS('PAY Payroll'!C4:C13,">="&20000,'PAY Payroll'!C4:C13,"<"&35000) -> 0
A23: Human Resources | B23: =COUNTIF('EMP Employees'!$M$3:$M$52,A23) -> 0 | D23: N$35-60k | E23: =COUNTIFS('PAY Payroll'!C4:C13,">="&35000,'PAY Payroll'!C4:C13,"<"&60000) -> 0
A24: Operations | B24: =COUNTIF('EMP Employees'!$M$3:$M$52,A24) -> 0 | D24: >N$60k | E24: =COUNTIFS('PAY Payroll'!C4:C13,">="&60000) -> 0
A25: Sales & Marketing | B25: =COUNTIF('EMP Employees'!$M$3:$M$52,A25) -> 0
A26: Information Technology | B26: =COUNTIF('EMP Employees'!$M$3:$M$52,A26) -> 0
A27: Legal & Compliance | B27: =COUNTIF('EMP Employees'!$M$3:$M$52,A27) -> 0

Sheet EMP Employees
A1: GENESIS HR · EMPLOYEE MASTER DATABASE
A2: Emp ID | B2: Full Name | C2: ID Number | D2: Date of Birth | E2: Gender | F2: NINO / SSC No. | G2: Tax ID (Taxpayer) | H2: Cell Number | I2: Email Address | J2: Bank & Account No. | K2: Branch Code | L2: Date of Hire | M2: Department | N2: Position / Title | O2: Manager | P2: Contract Type | Q2: Contract End Date | R2: Pay Type | S2: Hourly Rate (N$) | T2: Basic Monthly Salary (N$) | U2: Status | V2: Age
V3: =IFERROR(DATEDIF(D3,TODAY(),"Y"),"") -> 126
V4: =IFERROR(DATEDIF(D4,TODAY(),"Y"),"") -> 126
V5: =IFERROR(DATEDIF(D5,TODAY(),"Y"),"") -> 126
V6: =IFERROR(DATEDIF(D6,TODAY(),"Y"),"") -> 126
V7: =IFERROR(DATEDIF(D7,TODAY(),"Y"),"") -> 126
V8: =IFERROR(DATEDIF(D8,TODAY(),"Y"),"") -> 126
V9: =IFERROR(DATEDIF(D9,TODAY(),"Y"),"") -> 126
V10: =IFERROR(DATEDIF(D10,TODAY(),"Y"),"") -> 126
V11: =IFERROR(DATEDIF(D11,TODAY(),"Y"),"") -> 126
V12: =IFERROR(DATEDIF(D12,TODAY(),"Y"),"") -> 126
V13: =IFERROR(DATEDIF(D13,TODAY(),"Y"),"") -> 126
V14: =IFERROR(DATEDIF(D14,TODAY(),"Y"),"") -> 126
... V52: =IFERROR(DATEDIF(D52,TODAY(),"Y"),"") -> 126
A54: Blue cells = editable inputs | Dropdowns: Gender, Department, Contract Type, Pay Type, Status | Hourly Rate for hourly employees; Basic Salary for monthly employees
A55: =IF(COUNTA(A3:A52)=0,"Next ID: UN01","Next ID: UN"&TEXT(COUNTA(A3:A52)+1,"00")) -> Next ID: UN01

Sheet PAY Payroll
A1: GENESIS HR · PAYROLL ENGINE — NAMIBIA COMPLIANT (NamRA) — Labour Act 2007
A2: EMPLOYEE | E2: HOURS WORKED (INPUTS) | L2: EARNINGS | U2: GROSS | V2: DEDUCTIONS | AB2: TOTAL | AC2: NET PAY | AD2: YEAR-TO-DATE
A3: Emp ID | B3: Name | C3: Pay Type | D3: Hourly Rate | E3: Normal Hours | F3: Normal Overtime | G3: Night Hours @ 6% | H3: Night Hours Overtime | I3: P.Holiday @ Normal | J3: Sunday/P.Hol @ Double | K3: Leave Days | L3: Basic Salary (Monthly) | M3: Normal Hour Salary | N3: Normal OT Salary | O3: Night Hours Salary | P3: Night OT Salary | Q3: P.Holiday Normal Sal | R3: P.Holiday Double Sal | S3: Allowance | T3: Bonus | U3: Gross Salary | V3: PAYE (Tax) | W3: SSC Employee | X3: Pension Deduct. | Y3: Medical Aid | Z3: Other Deductions | AA3: Employee Savings | AB3: Total Deductions | AC3: Net Pay | AD3: YTD Gross | AE3: YTD Tax | AF3: Department | AG3: Designation
B4: =IF(A4="","",IFERROR(VLOOKUP(A4,'EMP Employees'!$A:$V,2,0),"")) | C4: =IF(A4="","",IFERROR(VLOOKUP(A4,'EMP Employees'!$A:$V,18,0),"")) | D4: =IF(A4="","",IFERROR(IF(C4="Hourly",VLOOKUP(A4,'EMP Employees'!$A:$V,19,0),IF(C4="Monthly",VLOOKUP(A4,'EMP Employees'!$A:$V,20,0)/'SET Settings'!$B$87,0)),0)) | L4: =IF($A4="","",IFERROR(IF(C4="Monthly",VLOOKUP(A4,'EMP Employees'!$A:$V,20,0),0),0)) | M4: =IF($A4="","",IFERROR(E4*D4,0)) | N4: =IF($A4="","",IFERROR(F4*D4*'SET Settings'!$B$70,0)) | O4: =IF($A4="","",IFERROR(G4*D4*(1+'SET Settings'!$B$71),0)) | P4: =IF($A4="","",IFERROR(H4*D4*'SET Settings'!$B$72,0)) | Q4: =IF($A4="","",IFERROR(I4*D4*'SET Settings'!$B$73,0)) | R4: =IF($A4="","",IFERROR(J4*D4*'SET Settings'!$B$74,0)) | U4: =IF($A4="","",IFERROR(L4+M4+N4+O4+P4+Q4+R4+S4+T4,0)) | V4: =IF($A4="","",ROUND(IFERROR(MAX(0,(INDEX('SET Settings'!$D$6:$D$12,MATCH(U4*12,'SET Settings'!$A$6:$A$12,1))+(U4*12-INDEX('SET Settings'!$A$6:$A$12,MATCH(U4*12,'SET Settings'!$A$6:$A$12,1)))*INDEX('SET Settings'!$C$6:$C$12,MATCH(U4*12,'SET Settings'!$A$6:$A$12,1))/100))/12,0),2)) | W4: =IF($A4="","",IFERROR(MIN(U4*'SET Settings'!$B$16,'SET Settings'!$B$18),0)) | AB4: =IF($A4="","",IFERROR(V4+W4+X4+Y4+Z4+AA4,0)) | AC4: =IF($A4="","",IFERROR(U4-AB4,0)) | AD4: =IF($A4="","",IFERROR(VLOOKUP(A4,'HIST Monthly History'!$A:$O,15,0),0)) | AE4: =IF($A4="","",IFERROR(V4*MONTH(TODAY()),0)) | AF4: =IF(A4="","",IFERROR(VLOOKUP(A4,'EMP Employees'!$A:$V,13,0),"")) | AG4: =IF(A4="","",IFERROR(VLOOKUP(A4,'EMP Employees'!$A:$V,14,0),""))
B5: =IF(A5="","",IFERROR(VLOOKUP(A5,'EMP Employees'!$A:$V,2,0),"")) | C5: =IF(A5="","",IFERROR(VLOOKUP(A5,'EMP Employees'!$A:$V,18,0),"")) | D5: =IF(A5="","",IFERROR(IF(C5="Hourly",VLOOKUP(A5,'EMP Employees'!$A:$V,19,0),IF(C5="Monthly",VLOOKUP(A5,'EMP Employees'!$A:$V,20,0)/'SET Settings'!$B$87,0)),0)) | L5: =IF($A5="","",IFERROR(IF(C5="Monthly",VLOOKUP(A5,'EMP Employees'!$A:$V,20,0),0),0)) | M5: =IF($A5="","",IFERROR(E5*D5,0)) | N5: =IF($A5="","",IFERROR(F5*D5*'SET Settings'!$B$70,0)) | O5: =IF($A5="","",IFERROR(G5*D5*(1+'SET Settings'!$B$71),0)) | P5: =IF($A5="","",IFERROR(H5*D5*'SET Settings'!$B$72,0)) | Q5: =IF($A5="","",IFERROR(I5*D5*'SET Settings'!$B$73,0)) | R5: =IF($A5="","",IFERROR(J5*D5*'SET Settings'!$B$74,0)) | U5: =IF($A5="","",IFERROR(L5+M5+N5+O5+P5+Q5+R5+S5+T5,0)) | V5: =IF($A5="","",ROUND(IFERROR(MAX(0,(INDEX('SET Settings'!$D$6:$D$12,MATCH(U5*12,'SET Settings'!$A$6:$A$12,1))+(U5*12-INDEX('SET Settings'!$A$6:$A$12,MATCH(U5*12,'SET Settings'!$A$6:$A$12,1)))*INDEX('SET Settings'!$C$6:$C$12,MATCH(U5*12,'SET Settings'!$A$6:$A$12,1))/100))/12,0),2)) | W5: =IF($A5="","",IFERROR(MIN(U5*'SET Settings'!$B$16,'SET Settings'!$B$18),0)) | AB5: =IF($A5="","",IFERROR(V5+W5+X5+Y5+Z5+AA5,0)) | AC5: =IF($A5="","",IFERROR(U5-AB5,0)) | AD5: =IF($A5="","",IFERROR(VLOOKUP(A5,'HIST Monthly History'!$A:$O,15,0),0)) | AE5: =IF($A5="","",IFERROR(V5*MONTH(TODAY()),0)) | AF5: =IF(A5="","",IFERROR(VLOOKUP(A5,'EMP Employees'!$A:$V,13,0),"")) | AG5: =IF(A5="","",IFERROR(VLOOKUP(A5,'EMP Employees'!$A:$V,14,0),""))
B6: =IF(A6="","",IFERROR(VLOOKUP(A6,'EMP Employees'!$A:$V,2,0),"")) | C6: =IF(A6="","",IFERROR(VLOOKUP(A6,'EMP Employees'!$A:$V,18,0),"")) | D6: =IF(A6="","",IFERROR(IF(C6="Hourly",VLOOKUP(A6,'EMP Employees'!$A:$V,19,0),IF(C6="Monthly",VLOOKUP(A6,'EMP Employees'!$A:$V,20,0)/'SET Settings'!$B$87,0)),0)) | L6: =IF($A6="","",IFERROR(IF(C6="Monthly",VLOOKUP(A6,'EMP Employees'!$A:$V,20,0),0),0)) | M6: =IF($A6="","",IFERROR(E6*D6,0)) | N6: =IF($A6="","",IFERROR(F6*D6*'SET Settings'!$B$70,0)) | O6: =IF($A6="","",IFERROR(G6*D6*(1+'SET Settings'!$B$71),0)) | P6: =IF($A6="","",IFERROR(H6*D6*'SET Settings'!$B$72,0)) | Q6: =IF($A6="","",IFERROR(I6*D6*'SET Settings'!$B$73,0)) | R6: =IF($A6="","",IFERROR(J6*D6*'SET Settings'!$B$74,0)) | U6: =IF($A6="","",IFERROR(L6+M6+N6+O6+P6+Q6+R6+S6+T6,0)) | V6: =IF($A6="","",ROUND(IFERROR(MAX(0,(INDEX('SET Settings'!$D$6:$D$12,MATCH(U6*12,'SET Settings'!$A$6:$A$12,1))+(U6*12-INDEX('SET Settings'!$A$6:$A$12,MATCH(U6*12,'SET Settings'!$A$6:$A$12,1)))*INDEX('SET Settings'!$C$6:$C$12,MATCH(U6*12,'SET Settings'!$A$6:$A$12,1))/100))/12,0),2)) | W6: =IF($A6="","",IFERROR(MIN(U6*'SET Settings'!$B$16,'SET Settings'!$B$18),0)) | AB6: =IF($A6="","",IFERROR(V6+W6+X6+Y6+Z6+AA6,0)) | AC6: =IF($A6="","",IFERROR(U6-AB6,0)) | AD6: =IF($A6="","",IFERROR(VLOOKUP(A6,'HIST Monthly History'!$A:$O,15,0),0)) | AE6: =IF($A6="","",IFERROR(V6*MONTH(TODAY()),0)) | AF6: =IF(A6="","",IFERROR(VLOOKUP(A6,'EMP Employees'!$A:$V,13,0),"")) | AG6: =IF(A6="","",IFERROR(VLOOKUP(A6,'EMP Employees'!$A:$V,14,0),""))
B7: =IF(A7="","",IFERROR(VLOOKUP(A7,'EMP Employees'!$A:$V,2,0),"")) | C7: =IF(A7="","",IFERROR(VLOOKUP(A7,'EMP Employees'!$A:$V,18,0),"")) | D7: =IF(A7="","",IFERROR(IF(C7="Hourly",VLOOKUP(A7,'EMP Employees'!$A:$V,19,0),IF(C7="Monthly",VLOOKUP(A7,'EMP Employees'!$A:$V,20,0)/'SET Settings'!$B$87,0)),0)) | L7: =IF($A7="","",IFERROR(IF(C7="Monthly",VLOOKUP(A7,'EMP Employees'!$A:$V,20,0),0),0)) | M7: =IF($A7="","",IFERROR(E7*D7,0)) | N7: =IF($A7="","",IFERROR(F7*D7*'SET Settings'!$B$70,0)) | O7: =IF($A7="","",IFERROR(G7*D7*(1+'SET Settings'!$B$71),0)) | P7: =IF($A7="","",IFERROR(H7*D7*'SET Settings'!$B$72,0)) | Q7: =IF($A7="","",IFERROR(I7*D7*'SET Settings'!$B$73,0)) | R7: =IF($A7="","",IFERROR(J7*D7*'SET Settings'!$B$74,0)) | U7: =IF($A7="","",IFERROR(L7+M7+N7+O7+P7+Q7+R7+S7+T7,0)) | V7: =IF($A7="","",ROUND(IFERROR(MAX(0,(INDEX('SET Settings'!$D$6:$D$12,MATCH(U7*12,'SET Settings'!$A$6:$A$12,1))+(U7*12-INDEX('SET Settings'!$A$6:$A$12,MATCH(U7*12,'SET Settings'!$A$6:$A$12,1)))*INDEX('SET Settings'!$C$6:$C$12,MATCH(U7*12,'SET Settings'!$A$6:$A$12,1))/100))/12,0),2)) | W7: =IF($A7="","",IFERROR(MIN(U7*'SET Settings'!$B$16,'SET Settings'!$B$18),0)) | AB7: =IF($A7="","",IFERROR(V7+W7+X7+Y7+Z7+AA7,0)) | AC7: =IF($A7="","",IFERROR(U7-AB7,0)) | AD7: =IF($A7="","",IFERROR(VLOOKUP(A7,'HIST Monthly History'!$A:$O,15,0),0)) | AE7: =IF($A7="","",IFERROR(V7*MONTH(TODAY()),0)) | AF7: =IF(A7="","",IFERROR(VLOOKUP(A7,'EMP Employees'!$A:$V,13,0),"")) | AG7: =IF(A7="","",IFERROR(VLOOKUP(A7,'EMP Employees'!$A:$V,14,0),""))
B8: =IF(A8="","",IFERROR(VLOOKUP(A8,'EMP Employees'!$A:$V,2,0),"")) | C8: =IF(A8="","",IFERROR(VLOOKUP(A8,'EMP Employees'!$A:$V,18,0),"")) | D8: =IF(A8="","",IFERROR(IF(C8="Hourly",VLOOKUP(A8,'EMP Employees'!$A:$V,19,0),IF(C8="Monthly",VLOOKUP(A8,'EMP Employees'!$A:$V,20,0)/'SET Settings'!$B$87,0)),0)) | L8: =IF($A8="","",IFERROR(IF(C8="Monthly",VLOOKUP(A8,'EMP Employees'!$A:$V,20,0),0),0)) | M8: =IF($A8="","",IFERROR(E8*D8,0)) | N8: =IF($A8="","",IFERROR(F8*D8*'SET Settings'!$B$70,0)) | O8: =IF($A8="","",IFERROR(G8*D8*(1+'SET Settings'!$B$71),0)) | P8: =IF($A8="","",IFERROR(H8*D8*'SET Settings'!$B$72,0)) | Q8: =IF($A8="","",IFERROR(I8*D8*'SET Settings'!$B$73,0)) | R8: =IF($A8="","",IFERROR(J8*D8*'SET Settings'!$B$74,0)) | U8: =IF($A8="","",IFERROR(L8+M8+N8+O8+P8+Q8+R8+S8+T8,0)) | V8: =IF($A8="","",ROUND(IFERROR(MAX(0,(INDEX('SET Settings'!$D$6:$D$12,MATCH(U8*12,'SET Settings'!$A$6:$A$12,1))+(U8*12-INDEX('SET Settings'!$A$6:$A$12,MATCH(U8*12,'SET Settings'!$A$6:$A$12,1)))*INDEX('SET Settings'!$C$6:$C$12,MATCH(U8*12,'SET Settings'!$A$6:$A$12,1))/100))/12,0),2)) | W8: =IF($A8="","",IFERROR(MIN(U8*'SET Settings'!$B$16,'SET Settings'!$B$18),0)) | AB8: =IF($A8="","",IFERROR(V8+W8+X8+Y8+Z8+AA8,0)) | AC8: =IF($A8="","",IFERROR(U8-AB8,0)) | AD8: =IF($A8="","",IFERROR(VLOOKUP(A8,'HIST Monthly History'!$A:$O,15,0),0)) | AE8: =IF($A8="","",IFERROR(V8*MONTH(TODAY()),0)) | AF8: =IF(A8="","",IFERROR(VLOOKUP(A8,'EMP Employees'!$A:$V,13,0),"")) | AG8: =IF(A8="","",IFERROR(VLOOKUP(A8,'EMP Employees'!$A:$V,14,0),""))
B9: =IF(A9="","",IFERROR(VLOOKUP(A9,'EMP Employees'!$A:$V,2,0),"")) | C9: =IF(A9="","",IFERROR(VLOOKUP(A9,'EMP Employees'!$A:$V,18,0),"")) | D9: =IF(A9="","",IFERROR(IF(C9="Hourly",VLOOKUP(A9,'EMP Employees'!$A:$V,19,0),IF(C9="Monthly",VLOOKUP(A9,'EMP Employees'!$A:$V,20,0)/'SET Settings'!$B$87,0)),0)) | L9: =IF($A9="","",IFERROR(IF(C9="Monthly",VLOOKUP(A9,'EMP Employees'!$A:$V,20,0),0),0)) | M9: =IF($A9="","",IFERROR(E9*D9,0)) | N9: =IF($A9="","",IFERROR(F9*D9*'SET Settings'!$B$70,0)) | O9: =IF($A9="","",IFERROR(G9*D9*(1+'SET Settings'!$B$71),0)) | P9: =IF($A9="","",IFERROR(H9*D9*'SET Settings'!$B$72,0)) | Q9: =IF($A9="","",IFERROR(I9*D9*'SET Settings'!$B$73,0)) | R9: =IF($A9="","",IFERROR(J9*D9*'SET Settings'!$B$74,0)) | U9: =IF($A9="","",IFERROR(L9+M9+N9+O9+P9+Q9+R9+S9+T9,0)) | V9: =IF($A9="","",ROUND(IFERROR(MAX(0,(INDEX('SET Settings'!$D$6:$D$12,MATCH(U9*12,'SET Settings'!$A$6:$A$12,1))+(U9*12-INDEX('SET Settings'!$A$6:$A$12,MATCH(U9*12,'SET Settings'!$A$6:$A$12,1)))*INDEX('SET Settings'!$C$6:$C$12,MATCH(U9*12,'SET Settings'!$A$6:$A$12,1))/100))/12,0),2)) | W9: =IF($A9="","",IFERROR(MIN(U9*'SET Settings'!$B$16,'SET Settings'!$B$18),0)) | AB9: =IF($A9="","",IFERROR(V9+W9+X9+Y9+Z9+AA9,0)) | AC9: =IF($A9="","",IFERROR(U9-AB9,0)) | AD9: =IF($A9="","",IFERROR(VLOOKUP(A9,'HIST Monthly History'!$A:$O,15,0),0)) | AE9: =IF($A9="","",IFERROR(V9*MONTH(TODAY()),0)) | AF9: =IF(A9="","",IFERROR(VLOOKUP(A9,'EMP Employees'!$A:$V,13,0),"")) | AG9: =IF(A9="","",IFERROR(VLOOKUP(A9,'EMP Employees'!$A:$V,14,0),""))
B10: =IF(A10="","",IFERROR(VLOOKUP(A10,'EMP Employees'!$A:$V,2,0),"")) | C10: =IF(A10="","",IFERROR(VLOOKUP(A10,'EMP Employees'!$A:$V,18,0),"")) | D10: =IF(A10="","",IFERROR(IF(C10="Hourly",VLOOKUP(A10,'EMP Employees'!$A:$V,19,0),IF(C10="Monthly",VLOOKUP(A10,'EMP Employees'!$A:$V,20,0)/'SET Settings'!$B$87,0)),0)) | L10: =IF($A10="","",IFERROR(IF(C10="Monthly",VLOOKUP(A10,'EMP Employees'!$A:$V,20,0),0),0)) | M10: =IF($A10="","",IFERROR(E10*D10,0)) | N10: =IF($A10="","",IFERROR(F10*D10*'SET Settings'!$B$70,0)) | O10: =IF($A10="","",IFERROR(G10*D10*(1+'SET Settings'!$B$71),0)) | P10: =IF($A10="","",IFERROR(H10*D10*'SET Settings'!$B$72,0)) | Q10: =IF($A10="","",IFERROR(I10*D10*'SET Settings'!$B$73,0)) | R10: =IF($A10="","",IFERROR(J10*D10*'SET Settings'!$B$74,0)) | U10: =IF($A10="","",IFERROR(L10+M10+N10+O10+P10+Q10+R10+S10+T10,0)) | V10: =IF($A10="","",ROUND(IFERROR(MAX(0,(INDEX('SET Settings'!$D$6:$D$12,MATCH(U10*12,'SET Settings'!$A$6:$A$12,1))+(U10*12-INDEX('SET Settings'!$A$6:$A$12,MATCH(U10*12,'SET Settings'!$A$6:$A$12,1)))*INDEX('SET Settings'!$C$6:$C$12,MATCH(U10*12,'SET Settings'!$A$6:$A$12,1))/100))/12,0),2)) | W10: =IF($A10="","",IFERROR(MIN(U10*'SET Settings'!$B$16,'SET Settings'!$B$18),0)) | AB10: =IF($A10="","",IFERROR(V10+W10+X10+Y10+Z10+AA10,0)) | AC10: =IF($A10="","",IFERROR(U10-AB10,0)) | AD10: =IF($A10="","",IFERROR(VLOOKUP(A10,'HIST Monthly History'!$A:$O,15,0),0)) | AE10: =IF($A10="","",IFERROR(V10*MONTH(TODAY()),0)) | AF10: =IF(A10="","",IFERROR(VLOOKUP(A10,'EMP Employees'!$A:$V,13,0),"")) | AG10: =IF(A10="","",IFERROR(VLOOKUP(A10,'EMP Employees'!$A:$V,14,0),""))
B11: =IF(A11="","",IFERROR(VLOOKUP(A11,'EMP Employees'!$A:$V,2,0),"")) | C11: =IF(A11="","",IFERROR(VLOOKUP(A11,'EMP Employees'!$A:$V,18,0),"")) | D11: =IF(A11="","",IFERROR(IF(C11="Hourly",VLOOKUP(A11,'EMP Employees'!$A:$V,19,0),IF(C11="Monthly",VLOOKUP(A11,'EMP Employees'!$A:$V,20,0)/'SET Settings'!$B$87,0)),0)) | L11: =IF($A11="","",IFERROR(IF(C11="Monthly",VLOOKUP(A11,'EMP Employees'!$A:$V,20,0),0),0)) | M11: =IF($A11="","",IFERROR(E11*D11,0)) | N11: =IF($A11="","",IFERROR(F11*D11*'SET Settings'!$B$70,0)) | O11: =IF($A11="","",IFERROR(G11*D11*(1+'SET Settings'!$B$71),0)) | P11: =IF($A11="","",IFERROR(H11*D11*'SET Settings'!$B$72,0)) | Q11: =IF($A11="","",IFERROR(I11*D11*'SET Settings'!$B$73,0)) | R11: =IF($A11="","",IFERROR(J11*D11*'SET Settings'!$B$74,0)) | U11: =IF($A11="","",IFERROR(L11+M11+N11+O11+P11+Q11+R11+S11+T11,0)) | V11: =IF($A11="","",ROUND(IFERROR(MAX(0,(INDEX('SET Settings'!$D$6:$D$12,MATCH(U11*12,'SET Settings'!$A$6:$A$12,1))+(U11*12-INDEX('SET Settings'!$A$6:$A$12,MATCH(U11*12,'SET Settings'!$A$6:$A$12,1)))*INDEX('SET Settings'!$C$6:$C$12,MATCH(U11*12,'SET Settings'!$A$6:$A$12,1))/100))/12,0),2)) | W11: =IF($A11="","",IFERROR(MIN(U11*'SET Settings'!$B$16,'SET Settings'!$B$18),0)) | AB11: =IF($A11="","",IFERROR(V11+W11+X11+Y11+Z11+AA11,0)) | AC11: =IF($A11="","",IFERROR(U11-AB11,0)) | AD11: =IF($A11="","",IFERROR(VLOOKUP(A11,'HIST Monthly History'!$A:$O,15,0),0)) | AE11: =IF($A11="","",IFERROR(V11*MONTH(TODAY()),0)) | AF11: =IF(A11="","",IFERROR(VLOOKUP(A11,'EMP Employees'!$A:$V,13,0),"")) | AG11: =IF(A11="","",IFERROR(VLOOKUP(A11,'EMP Employees'!$A:$V,14,0),""))
B12: =IF(A12="","",IFERROR(VLOOKUP(A12,'EMP Employees'!$A:$V,2,0),"")) | C12: =IF(A12="","",IFERROR(VLOOKUP(A12,'EMP Employees'!$A:$V,18,0),"")) | D12: =IF(A12="","",IFERROR(IF(C12="Hourly",VLOOKUP(A12,'EMP Employees'!$A:$V,19,0),IF(C12="Monthly",VLOOKUP(A12,'EMP Employees'!$A:$V,20,0)/'SET Settings'!$B$87,0)),0)) | L12: =IF($A12="","",IFERROR(IF(C12="Monthly",VLOOKUP(A12,'EMP Employees'!$A:$V,20,0),0),0)) | M12: =IF($A12="","",IFERROR(E12*D12,0)) | N12: =IF($A12="","",IFERROR(F12*D12*'SET Settings'!$B$70,0)) | O12: =IF($A12="","",IFERROR(G12*D12*(1+'SET Settings'!$B$71),0)) | P12: =IF($A12="","",IFERROR(H12*D12*'SET Settings'!$B$72,0)) | Q12: =IF($A12="","",IFERROR(I12*D12*'SET Settings'!$B$73,0)) | R12: =IF($A12="","",IFERROR(J12*D12*'SET Settings'!$B$74,0)) | U12: =IF($A12="","",IFERROR(L12+M12+N12+O12+P12+Q12+R12+S12+T12,0)) | V12: =IF($A12="","",ROUND(IFERROR(MAX(0,(INDEX('SET Settings'!$D$6:$D$12,MATCH(U12*12,'SET Settings'!$A$6:$A$12,1))+(U12*12-INDEX('SET Settings'!$A$6:$A$12,MATCH(U12*12,'SET Settings'!$A$6:$A$12,1)))*INDEX('SET Settings'!$C$6:$C$12,MATCH(U12*12,'SET Settings'!$A$6:$A$12,1))/100))/12,0),2)) | W12: =IF($A12="","",IFERROR(MIN(U12*'SET Settings'!$B$16,'SET Settings'!$B$18),0)) | AB12: =IF($A12="","",IFERROR(V12+W12+X12+Y12+Z12+AA12,0)) | AC12: =IF($A12="","",IFERROR(U12-AB12,0)) | AD12: =IF($A12="","",IFERROR(VLOOKUP(A12,'HIST Monthly History'!$A:$O,15,0),0)) | AE12: =IF($A12="","",IFERROR(V12*MONTH(TODAY()),0)) | AF12: =IF(A12="","",IFERROR(VLOOKUP(A12,'EMP Employees'!$A:$V,13,0),"")) | AG12: =IF(A12="","",IFERROR(VLOOKUP(A12,'EMP Employees'!$A:$V,14,0),""))
B13: =IF(A13="","",IFERROR(VLOOKUP(A13,'EMP Employees'!$A:$V,2,0),"")) | C13: =IF(A13="","",IFERROR(VLOOKUP(A13,'EMP Employees'!$A:$V,18,0),"")) | D13: =IF(A13="","",IFERROR(IF(C13="Hourly",VLOOKUP(A13,'EMP Employees'!$A:$V,19,0),IF(C13="Monthly",VLOOKUP(A13,'EMP Employees'!$A:$V,20,0)/'SET Settings'!$B$87,0)),0)) | L13: =IF($A13="","",IFERROR(IF(C13="Monthly",VLOOKUP(A13,'EMP Employees'!$A:$V,20,0),0),0)) | M13: =IF($A13="","",IFERROR(E13*D13,0)) | N13: =IF($A13="","",IFERROR(F13*D13*'SET Settings'!$B$70,0)) | O13: =IF($A13="","",IFERROR(G13*D13*(1+'SET Settings'!$B$71),0)) | P13: =IF($A13="","",IFERROR(H13*D13*'SET Settings'!$B$72,0)) | Q13: =IF($A13="","",IFERROR(I13*D13*'SET Settings'!$B$73,0)) | R13: =IF($A13="","",IFERROR(J13*D13*'SET Settings'!$B$74,0)) | U13: =IF($A13="","",IFERROR(L13+M13+N13+O13+P13+Q13+R13+S13+T13,0)) | V13: =IF($A13="","",ROUND(IFERROR(MAX(0,(INDEX('SET Settings'!$D$6:$D$12,MATCH(U13*12,'SET Settings'!$A$6:$A$12,1))+(U13*12-INDEX('SET Settings'!$A$6:$A$12,MATCH(U13*12,'SET Settings'!$A$6:$A$12,1)))*INDEX('SET Settings'!$C$6:$C$12,MATCH(U13*12,'SET Settings'!$A$6:$A$12,1))/100))/12,0),2)) | W13: =IF($A13="","",IFERROR(MIN(U13*'SET Settings'!$B$16,'SET Settings'!$B$18),0)) | AB13: =IF($A13="","",IFERROR(V13+W13+X13+Y13+Z13+AA13,0)) | AC13: =IF($A13="","",IFERROR(U13-AB13,0)) | AD13: =IF($A13="","",IFERROR(VLOOKUP(A13,'HIST Monthly History'!$A:$O,15,0),0)) | AE13: =IF($A13="","",IFERROR(V13*MONTH(TODAY()),0)) | AF13: =IF(A13="","",IFERROR(VLOOKUP(A13,'EMP Employees'!$A:$V,13,0),"")) | AG13: =IF(A13="","",IFERROR(VLOOKUP(A13,'EMP Employees'!$A:$V,14,0),""))
B14: =IF(A14="","",IFERROR(VLOOKUP(A14,'EMP Employees'!$A:$V,2,0),"")) | C14: =IF(A14="","",IFERROR(VLOOKUP(A14,'EMP Employees'!$A:$V,18,0),"")) | D14: =IF(A14="","",IFERROR(IF(C14="Hourly",VLOOKUP(A14,'EMP Employees'!$A:$V,19,0),IF(C14="Monthly",VLOOKUP(A14,'EMP Employees'!$A:$V,20,0)/'SET Settings'!$B$87,0)),0)) | L14: =IF($A14="","",IFERROR(IF(C14="Monthly",VLOOKUP(A14,'EMP Employees'!$A:$V,20,0),0),0)) | M14: =IF($A14="","",IFERROR(E14*D14,0)) | N14: =IF($A14="","",IFERROR(F14*D14*'SET Settings'!$B$70,0)) | O14: =IF($A14="","",IFERROR(G14*D14*(1+'SET Settings'!$B$71),0)) | P14: =IF($A14="","",IFERROR(H14*D14*'SET Settings'!$B$72,0)) | Q14: =IF($A14="","",IFERROR(I14*D14*'SET Settings'!$B$73,0)) | R14: =IF($A14="","",IFERROR(J14*D14*'SET Settings'!$B$74,0)) | U14: =IF($A14="","",IFERROR(L14+M14+N14+O14+P14+Q14+R14+S14+T14,0)) | V14: =IF($A14="","",ROUND(IFERROR(MAX(0,(INDEX('SET Settings'!$D$6:$D$12,MATCH(U14*12,'SET Settings'!$A$6:$A$12,1))+(U14*12-INDEX('SET Settings'!$A$6:$A$12,MATCH(U14*12,'SET Settings'!$A$6:$A$12,1)))*INDEX('SET Settings'!$C$6:$C$12,MATCH(U14*12,'SET Settings'!$A$6:$A$12,1))/100))/12,0),2)) | W14: =IF($A14="","",IFERROR(MIN(U14*'SET Settings'!$B$16,'SET Settings'!$B$18),0)) | AB14: =IF($A14="","",IFERROR(V14+W14+X14+Y14+Z14+AA14,0)) | AC14: =IF($A14="","",IFERROR(U14-AB14,0)) | AD14: =IF($A14="","",IFERROR(VLOOKUP(A14,'HIST Monthly History'!$A:$O,15,0),0)) | AE14: =IF($A14="","",IFERROR(V14*MONTH(TODAY()),0)) | AF14: =IF(A14="","",IFERROR(VLOOKUP(A14,'EMP Employees'!$A:$V,13,0),"")) | AG14: =IF(A14="","",IFERROR(VLOOKUP(A14,'EMP Employees'!$A:$V,14,0),""))
B15: =IF(A15="","",IFERROR(VLOOKUP(A15,'EMP Employees'!$A:$V,2,0),"")) | C15: =IF(A15="","",IFERROR(VLOOKUP(A15,'EMP Employees'!$A:$V,18,0),"")) | D15: =IF(A15="","",IFERROR(IF(C15="Hourly",VLOOKUP(A15,'EMP Employees'!$A:$V,19,0),IF(C15="Monthly",VLOOKUP(A15,'EMP Employees'!$A:$V,20,0)/'SET Settings'!$B$87,0)),0)) | L15: =IF($A15="","",IFERROR(IF(C15="Monthly",VLOOKUP(A15,'EMP Employees'!$A:$V,20,0),0),0)) | M15: =IF($A15="","",IFERROR(E15*D15,0)) | N15: =IF($A15="","",IFERROR(F15*D15*'SET Settings'!$B$70,0)) | O15: =IF($A15="","",IFERROR(G15*D15*(1+'SET Settings'!$B$71),0)) | P15: =IF($A15="","",IFERROR(H15*D15*'SET Settings'!$B$72,0)) | Q15: =IF($A15="","",IFERROR(I15*D15*'SET Settings'!$B$73,0)) | R15: =IF($A15="","",IFERROR(J15*D15*'SET Settings'!$B$74,0)) | U15: =IF($A15="","",IFERROR(L15+M15+N15+O15+P15+Q15+R15+S15+T15,0)) | V15: =IF($A15="","",ROUND(IFERROR(MAX(0,(INDEX('SET Settings'!$D$6:$D$12,MATCH(U15*12,'SET Settings'!$A$6:$A$12,1))+(U15*12-INDEX('SET Settings'!$A$6:$A$12,MATCH(U15*12,'SET Settings'!$A$6:$A$12,1)))*INDEX('SET Settings'!$C$6:$C$12,MATCH(U15*12,'SET Settings'!$A$6:$A$12,1))/100))/12,0),2)) | W15: =IF($A15="","",IFERROR(MIN(U15*'SET Settings'!$B$16,'SET Settings'!$B$18),0)) | AB15: =IF($A15="","",IFERROR(V15+W15+X15+Y15+Z15+AA15,0)) | AC15: =IF($A15="","",IFERROR(U15-AB15,0)) | AD15: =IF($A15="","",IFERROR(VLOOKUP(A15,'HIST Monthly History'!$A:$O,15,0),0)) | AE15: =IF($A15="","",IFERROR(V15*MONTH(TODAY()),0)) | AF15: =IF(A15="","",IFERROR(VLOOKUP(A15,'EMP Employees'!$A:$V,13,0),"")) | AG15: =IF(A15="","",IFERROR(VLOOKUP(A15,'EMP Employees'!$A:$V,14,0),""))
... B53: =IF(A53="","",IFERROR(VLOOKUP(A53,'EMP Employees'!$A:$V,2,0),"")) | C53: =IF(A53="","",IFERROR(VLOOKUP(A53,'EMP Employees'!$A:$V,18,0),"")) | D53: =IF(A53="","",IFERROR(IF(C53="Hourly",VLOOKUP(A53,'EMP Employees'!$A:$V,19,0),IF(C53="Monthly",VLOOKUP(A53,'EMP Employees'!$A:$V,20,0)/'SET Settings'!$B$87,0)),0)) | L53: =IF($A53="","",IFERROR(IF(C53="Monthly",VLOOKUP(A53,'EMP Employees'!$A:$V,20,0),0),0)) | M53: =IF($A53="","",IFERROR(E53*D53,0)) | N53: =IF($A53="","",IFERROR(F53*D53*'SET Settings'!$B$70,0)) | O53: =IF($A53="","",IFERROR(G53*D53*(1+'SET Settings'!$B$71),0)) | P53: =IF($A53="","",IFERROR(H53*D53*'SET Settings'!$B$72,0)) | Q53: =IF($A53="","",IFERROR(I53*D53*'SET Settings'!$B$73,0)) | R53: =IF($A53="","",IFERROR(J53*D53*'SET Settings'!$B$74,0)) | U53: =IF($A53="","",IFERROR(L53+M53+N53+O53+P53+Q53+R53+S53+T53,0)) | V53: =IF($A53="","",ROUND(IFERROR(MAX(0,(INDEX('SET Settings'!$D$6:$D$12,MATCH(U53*12,'SET Settings'!$A$6:$A$12,1))+(U53*12-INDEX('SET Settings'!$A$6:$A$12,MATCH(U53*12,'SET Settings'!$A$6:$A$12,1)))*INDEX('SET Settings'!$C$6:$C$12,MATCH(U53*12,'SET Settings'!$A$6:$A$12,1))/100))/12,0),2)) | W53: =IF($A53="","",IFERROR(MIN(U53*'SET Settings'!$B$16,'SET Settings'!$B$18),0)) | AB53: =IF($A53="","",IFERROR(V53+W53+X53+Y53+Z53+AA53,0)) | AC53: =IF($A53="","",IFERROR(U53-AB53,0)) | AD53: =IF($A53="","",IFERROR(VLOOKUP(A53,'HIST Monthly History'!$A:$O,15,0),0)) | AE53: =IF($A53="","",IFERROR(V53*MONTH(TODAY()),0)) | AF53: =IF(A53="","",IFERROR(VLOOKUP(A53,'EMP Employees'!$A:$V,13,0),"")) | AG53: =IF(A53="","",IFERROR(VLOOKUP(A53,'EMP Employees'!$A:$V,14,0),""))
A54: TOTALS | E54: =SUM(E4:E53) -> 0 | F54: =SUM(F4:F53) -> 0 | G54: =SUM(G4:G53) -> 0 | H54: =SUM(H4:H53) -> 0 | I54: =SUM(I4:I53) -> 0 | J54: =SUM(J4:J53) -> 0 | K54: =SUM(K4:K53) -> 0 | L54: =SUM(L4:L53) -> 0 | ... AE54: =SUM(AE4:AE53) -> 0
A55: Blue cells (Emp ID, Hours E-K, Allowance, Bonus, Pension, Medical, Other Ded, Savings) = Input — editable | All other cells = Protected formulas | Rates from Labour Act 2007

Sheet SLP Payslip
B1: Select Employee ID: | F1: Period:
B2: =IF(D1="","⚠ Enter an Employee ID in cell D1",IF(ISNA(VLOOKUP(D1,'EMP Employees'!A:B,2,0)),"⚠ Invalid Employee ID — please enter a valid ID in cell D1","")) -> ⚠ Enter an Employee ID in cell D1
B3: GENESIS (PTY) LTD
B4: 123 Independence Avenue, Windhoek, Namibia | Tel: +264 61 000 000 | VAT: N12345678
B6: PAYSLIP
B7: =IF(G1="",TEXT(TODAY(),"MMMM YYYY"),G1&" "&TEXT(TODAY(),"YYYY")) -> June 2026
B9: EMPLOYEE DETAILS
B10: Employee ID: | C10: =D1 -> 0 | E10: Pay Type: | F10: =IF($D$1="","",IFERROR(VLOOKUP($D$1,'EMP Employees'!$A:$V,18,0),""))
B11: Name: | C11: =IF($D$1="","",IFERROR(VLOOKUP($D$1,'EMP Employees'!$A:$V,2,0),"")) | E11: Hourly Rate: | F11: =IFERROR(VLOOKUP(D1,'PAY Payroll'!$A:$D,4,0),"")
B12: ID Number: | C12: =IF($D$1="","",IFERROR(VLOOKUP($D$1,'EMP Employees'!$A:$V,3,0),"")) | E12: Department: | F12: =IF($D$1="","",IFERROR(VLOOKUP($D$1,'EMP Employees'!$A:$V,13,0),""))
B13: SSC No.: | C13: =IF($D$1="","",IFERROR(VLOOKUP($D$1,'EMP Employees'!$A:$V,6,0),"")) | E13: Position: | F13: =IF($D$1="","",IFERROR(VLOOKUP($D$1,'EMP Employees'!$A:$V,14,0),""))
B14: Tax ID: | C14: =IF($D$1="","",IFERROR(VLOOKUP($D$1,'EMP Employees'!$A:$V,7,0),"")) | E14: Contract Type: | F14: =IF($D$1="","",IFERROR(VLOOKUP($D$1,'EMP Employees'!$A:$V,16,0),""))
B15: Date of Hire: | C15: =IFERROR(VLOOKUP(D1,'EMP Employees'!$A:$V,12,0),"") | E15: Status: | F15: =IF($D$1="","",IFERROR(VLOOKUP($D$1,'EMP Employees'!$A:$V,21,0),""))
B17: EARNINGS | E17: DEDUCTIONS
B18: Basic Salary | D18: =IFERROR(VLOOKUP(D1,'PAY Payroll'!$A:$AC,12,0),0) -> 0 | E18: PAYE (Income Tax) | H18: =IFERROR(VLOOKUP(D1,'PAY Payroll'!$A:$AC,22,0),0) -> 0
B19: Normal Hour Salary | D19: =IFERROR(VLOOKUP(D1,'PAY Payroll'!$A:$AC,13,0),0) -> 0 | E19: SSC Contribution | H19: =IFERROR(VLOOKUP(D1,'PAY Payroll'!$A:$AC,23,0),0) -> 0
B20: Normal Overtime Salary | D20: =IFERROR(VLOOKUP(D1,'PAY Payroll'!$A:$AC,14,0),0) -> 0 | E20: Pension Fund | H20: =IFERROR(VLOOKUP(D1,'PAY Payroll'!$A:$AC,24,0),0) -> 0
B21: Night Hours @ 6% Salary | D21: =IFERROR(VLOOKUP(D1,'PAY Payroll'!$A:$AC,15,0),0) -> 0 | E21: Medical Aid | H21: =IFERROR(VLOOKUP(D1,'PAY Payroll'!$A:$AC,25,0),0) -> 0
B22: Night Hours OT Salary | D22: =IFERROR(VLOOKUP(D1,'PAY Payroll'!$A:$AC,16,0),0) -> 0 | E22: Other Deductions | H22: =IFERROR(VLOOKUP(D1,'PAY Payroll'!$A:$AC,26,0),0) -> 0
B23: P.Holiday @ Normal Salary | D23: =IFERROR(VLOOKUP(D1,'PAY Payroll'!$A:$AC,17,0),0) -> 0 | E23: Employee Savings | H23: =IFERROR(VLOOKUP(D1,'PAY Payroll'!$A:$AC,27,0),0) -> 0
B24: P.Holiday/Sun @ Double Sal | D24: =IFERROR(VLOOKUP(D1,'PAY Payroll'!$A:$AC,18,0),0) -> 0 | E24: TOTAL DEDUCTIONS | H24: =IFERROR(VLOOKUP(D1,'PAY Payroll'!$A:$AC,28,0),0) -> 0
B25: Allowance | D25: =IFERROR(VLOOKUP(D1,'PAY Payroll'!$A:$AC,19,0),0) -> 0
B26: Bonus | D26: =IFERROR(VLOOKUP(D1,'PAY Payroll'!$A:$AC,20,0),0) -> 0
B27: GROSS SALARY | D27: =IFERROR(VLOOKUP(D1,'PAY Payroll'!$A:$AC,21,0),0) -> 0
B29: NET PAY | E29: =IFERROR(VLOOKUP(D1,'PAY Payroll'!$A:$AC,29,0),0) -> 0
B31: YEAR-TO-DATE SUMMARY
B32: YTD Gross | D32: =IFERROR(VLOOKUP(D1,'PAY Payroll'!$A:$AE,30,0),0) -> 0
B33: YTD Tax Paid | D33: =IFERROR(VLOOKUP(D1,'PAY Payroll'!$A:$AE,31,0),0) -> 0
B35: HOURS WORKED THIS PERIOD
B36: Normal Hours | D36: =IFERROR(VLOOKUP(D1,'PAY Payroll'!$A:$AC,5,0),0) -> 0
B37: Normal Overtime | D37: =IFERROR(VLOOKUP(D1,'PAY Payroll'!$A:$AC,6,0),0) -> 0
B38: Night Hours @ 6% | D38: =IFERROR(VLOOKUP(D1,'PAY Payroll'!$A:$AC,7,0),0) -> 0
B39: Night Hours OT | D39: =IFERROR(VLOOKUP(D1,'PAY Payroll'!$A:$AC,8,0),0) -> 0
B40: P.Holiday @ Normal | D40: =IFERROR(VLOOKUP(D1,'PAY Payroll'!$A:$AC,9,0),0) -> 0
B41: Sunday/P.Holiday @ Double | D41: =IFERROR(VLOOKUP(D1,'PAY Payroll'!$A:$AC,10,0),0) -> 0
B42: Leave Days | D42: =IFERROR(VLOOKUP(D1,'PAY Payroll'!$A:$AC,11,0),0) -> 0
B44: This payslip is system-generated and does not require a signature. | Genesis HR System | NamRA Compliant
B45: =TEXT(NOW(),"Generated on: DD MMM YYYY HH:MM") -> CE786n7865786at7863 on: 03 Tammuz 2026 14:01

Sheet LVE Leave
A1: GENESIS HR · LEAVE & ATTENDANCE TRACKER
A2: Emp ID | B2: Name | C2: Date of Hire | D2: Days Worked | E2: Leave Earned | F2: Leave Taken | G2: Balance | H2: Sick Days Used | I2: Maternity/Paternity | J2: Contract Type | K2: Contract End | L2: Leave at Exit
B3: =IFERROR(VLOOKUP(A3,'EMP Employees'!$A:$V,2,0),"") | C3: =IFERROR(VLOOKUP(A3,'EMP Employees'!$A:$V,12,0),"") | D3: =IFERROR(TODAY()-C3,0) -> 0 | E3: =IFERROR(INT(D3/17),0) -> 0 | G3: =IFERROR(E3-F3,0) -> 0 | H3: =IFERROR(SUMIFS('ABS Absence Log'!D:D,'ABS Absence Log'!A:A,A3,'ABS Absence Log'!C:C,"Sick Leave"),0) -> 0 | I3: =IFERROR(SUMIFS('ABS Absence Log'!D:D,'ABS Absence Log'!A:A,A3,'ABS Absence Log'!C:C,"Maternity Leave")+SUMIFS('ABS Absence Log'!D:D,'ABS Absence Log'!A:A,A3,'ABS Absence Log'!C:C,"Paternity Leave"),0) -> 0 | J3: =IFERROR(VLOOKUP(A3,'EMP Employees'!$A:$V,16,0),"") | K3: =IFERROR(VLOOKUP(A3,'EMP Employees'!$A:$V,17,0),"") | L3: =IFERROR(IF(AND(K3<>"",K3<TODAY()),G3,"N/A"),"") -> N/A
B4: =IFERROR(VLOOKUP(A4,'EMP Employees'!$A:$V,2,0),"") | C4: =IFERROR(VLOOKUP(A4,'EMP Employees'!$A:$V,12,0),"") | D4: =IFERROR(TODAY()-C4,0) -> 0 | E4: =IFERROR(INT(D4/17),0) -> 0 | G4: =IFERROR(E4-F4,0) -> 0 | H4: =IFERROR(SUMIFS('ABS Absence Log'!D:D,'ABS Absence Log'!A:A,A4,'ABS Absence Log'!C:C,"Sick Leave"),0) -> 0 | I4: =IFERROR(SUMIFS('ABS Absence Log'!D:D,'ABS Absence Log'!A:A,A4,'ABS Absence Log'!C:C,"Maternity Leave")+SUMIFS('ABS Absence Log'!D:D,'ABS Absence Log'!A:A,A4,'ABS Absence Log'!C:C,"Paternity Leave"),0) -> 0 | J4: =IFERROR(VLOOKUP(A4,'EMP Employees'!$A:$V,16,0),"") | K4: =IFERROR(VLOOKUP(A4,'EMP Employees'!$A:$V,17,0),"") | L4: =IFERROR(IF(AND(K4<>"",K4<TODAY()),G4,"N/A"),"") -> N/A
B5: =IFERROR(VLOOKUP(A5,'EMP Employees'!$A:$V,2,0),"") | C5: =IFERROR(VLOOKUP(A5,'EMP Employees'!$A:$V,12,0),"") | D5: =IFERROR(TODAY()-C5,0) -> 0 | E5: =IFERROR(INT(D5/17),0) -> 0 | G5: =IFERROR(E5-F5,0) -> 0 | H5: =IFERROR(SUMIFS('ABS Absence Log'!D:D,'ABS Absence Log'!A:A,A5,'ABS Absence Log'!C:C,"Sick Leave"),0) -> 0 | I5: =IFERROR(SUMIFS('ABS Absence Log'!D:D,'ABS Absence Log'!A:A,A5,'ABS Absence Log'!C:C,"Maternity Leave")+SUMIFS('ABS Absence Log'!D:D,'ABS Absence Log'!A:A,A5,'ABS Absence Log'!C:C,"Paternity Leave"),0) -> 0 | J5: =IFERROR(VLOOKUP(A5,'EMP Employees'!$A:$V,16,0),"") | K5: =IFERROR(VLOOKUP(A5,'EMP Employees'!$A:$V,17,0),"") | L5: =IFERROR(IF(AND(K5<>"",K5<TODAY()),G5,"N/A"),"") -> N/A
B6: =IFERROR(VLOOKUP(A6,'EMP Employees'!$A:$V,2,0),"") | C6: =IFERROR(VLOOKUP(A6,'EMP Employees'!$A:$V,12,0),"") | D6: =IFERROR(TODAY()-C6,0) -> 0 | E6: =IFERROR(INT(D6/17),0) -> 0 | G6: =IFERROR(E6-F6,0) -> 0 | H6: =IFERROR(SUMIFS('ABS Absence Log'!D:D,'ABS Absence Log'!A:A,A6,'ABS Absence Log'!C:C,"Sick Leave"),0) -> 0 | I6: =IFERROR(SUMIFS('ABS Absence Log'!D:D,'ABS Absence Log'!A:A,A6,'ABS Absence Log'!C:C,"Maternity Leave")+SUMIFS('ABS Absence Log'!D:D,'ABS Absence Log'!A:A,A6,'ABS Absence Log'!C:C,"Paternity Leave"),0) -> 0 | J6: =IFERROR(VLOOKUP(A6,'EMP Employees'!$A:$V,16,0),"") | K6: =IFERROR(VLOOKUP(A6,'EMP Employees'!$A:$V,17,0),"") | L6: =IFERROR(IF(AND(K6<>"",K6<TODAY()),G6,"N/A"),"") -> N/A
B7: =IFERROR(VLOOKUP(A7,'EMP Employees'!$A:$V,2,0),"") | C7: =IFERROR(VLOOKUP(A7,'EMP Employees'!$A:$V,12,0),"") | D7: =IFERROR(TODAY()-C7,0) -> 0 | E7: =IFERROR(INT(D7/17),0) -> 0 | G7: =IFERROR(E7-F7,0) -> 0 | H7: =IFERROR(SUMIFS('ABS Absence Log'!D:D,'ABS Absence Log'!A:A,A7,'ABS Absence Log'!C:C,"Sick Leave"),0) -> 0 | I7: =IFERROR(SUMIFS('ABS Absence Log'!D:D,'ABS Absence Log'!A:A,A7,'ABS Absence Log'!C:C,"Maternity Leave")+SUMIFS('ABS Absence Log'!D:D,'ABS Absence Log'!A:A,A7,'ABS Absence Log'!C:C,"Paternity Leave"),0) -> 0 | J7: =IFERROR(VLOOKUP(A7,'EMP Employees'!$A:$V,16,0),"") | K7: =IFERROR(VLOOKUP(A7,'EMP Employees'!$A:$V,17,0),"") | L7: =IFERROR(IF(AND(K7<>"",K7<TODAY()),G7,"N/A"),"") -> N/A
B8: =IFERROR(VLOOKUP(A8,'EMP Employees'!$A:$V,2,0),"") | C8: =IFERROR(VLOOKUP(A8,'EMP Employees'!$A:$V,12,0),"") | D8: =IFERROR(TODAY()-C8,0) -> 0 | E8: =IFERROR(IF(AND(K8<>"",K8<TODAY()),INT((K8-C8)/17),INT(D8/17)),0) -> 0 | G8: =IFERROR(E8-F8,0) -> 0 | H8: =IFERROR(SUMIFS('ABS Absence Log'!D:D,'ABS Absence Log'!A:A,A8,'ABS Absence Log'!C:C,"Sick Leave"),0) -> 0 | I8: =IFERROR(SUMIFS('ABS Absence Log'!D:D,'ABS Absence Log'!A:A,A8,'ABS Absence Log'!C:C,"Maternity Leave")+SUMIFS('ABS Absence Log'!D:D,'ABS Absence Log'!A:A,A8,'ABS Absence Log'!C:C,"Paternity Leave"),0) -> 0 | J8: =IFERROR(VLOOKUP(A8,'EMP Employees'!$A:$V,16,0),"") | K8: =IFERROR(VLOOKUP(A8,'EMP Employees'!$A:$V,17,0),"") | L8: =IFERROR(IF(AND(K8<>"",K8<TODAY()),G8,"N/A"),"") -> N/A
B9: =IFERROR(VLOOKUP(A9,'EMP Employees'!$A:$V,2,0),"") | C9: =IFERROR(VLOOKUP(A9,'EMP Employees'!$A:$V,12,0),"") | D9: =IFERROR(TODAY()-C9,0) -> 0 | E9: =IFERROR(INT(D9/17),0) -> 0 | G9: =IFERROR(E9-F9,0) -> 0 | H9: =IFERROR(SUMIFS('ABS Absence Log'!D:D,'ABS Absence Log'!A:A,A9,'ABS Absence Log'!C:C,"Sick Leave"),0) -> 0 | I9: =IFERROR(SUMIFS('ABS Absence Log'!D:D,'ABS Absence Log'!A:A,A9,'ABS Absence Log'!C:C,"Maternity Leave")+SUMIFS('ABS Absence Log'!D:D,'ABS Absence Log'!A:A,A9,'ABS Absence Log'!C:C,"Paternity Leave"),0) -> 0 | J9: =IFERROR(VLOOKUP(A9,'EMP Employees'!$A:$V,16,0),"") | K9: =IFERROR(VLOOKUP(A9,'EMP Employees'!$A:$V,17,0),"") | L9: =IFERROR(IF(AND(K9<>"",K9<TODAY()),G9,"N/A"),"") -> N/A
B10: =IFERROR(VLOOKUP(A10,'EMP Employees'!$A:$V,2,0),"") | C10: =IFERROR(VLOOKUP(A10,'EMP Employees'!$A:$V,12,0),"") | D10: =IFERROR(TODAY()-C10,0) -> 0 | E10: =IFERROR(INT(D10/17),0) -> 0 | G10: =IFERROR(E10-F10,0) -> 0 | H10: =IFERROR(SUMIFS('ABS Absence Log'!D:D,'ABS Absence Log'!A:A,A10,'ABS Absence Log'!C:C,"Sick Leave"),0) -> 0 | I10: =IFERROR(SUMIFS('ABS Absence Log'!D:D,'ABS Absence Log'!A:A,A10,'ABS Absence Log'!C:C,"Maternity Leave")+SUMIFS('ABS Absence Log'!D:D,'ABS Absence Log'!A:A,A10,'ABS Absence Log'!C:C,"Paternity Leave"),0) -> 0 | J10: =IFERROR(VLOOKUP(A10,'EMP Employees'!$A:$V,16,0),"") | K10: =IFERROR(VLOOKUP(A10,'EMP Employees'!$A:$V,17,0),"") | L10: =IFERROR(IF(AND(K10<>"",K10<TODAY()),G10,"N/A"),"") -> N/A
B11: =IFERROR(VLOOKUP(A11,'EMP Employees'!$A:$V,2,0),"") | C11: =IFERROR(VLOOKUP(A11,'EMP Employees'!$A:$V,12,0),"") | D11: =IFERROR(TODAY()-C11,0) -> 0 | E11: =IFERROR(IF(AND(K11<>"",K11<TODAY()),INT((K11-C11)/17),INT(D11/17)),0) -> 0 | G11: =IFERROR(E11-F11,0) -> 0 | H11: =IFERROR(SUMIFS('ABS Absence Log'!D:D,'ABS Absence Log'!A:A,A11,'ABS Absence Log'!C:C,"Sick Leave"),0) -> 0 | I11: =IFERROR(SUMIFS('ABS Absence Log'!D:D,'ABS Absence Log'!A:A,A11,'ABS Absence Log'!C:C,"Maternity Leave")+SUMIFS('ABS Absence Log'!D:D,'ABS Absence Log'!A:A,A11,'ABS Absence Log'!C:C,"Paternity Leave"),0) -> 0 | J11: =IFERROR(VLOOKUP(A11,'EMP Employees'!$A:$V,16,0),"") | K11: =IFERROR(VLOOKUP(A11,'EMP Employees'!$A:$V,17,0),"") | L11: =IFERROR(IF(AND(K11<>"",K11<TODAY()),G11,"N/A"),"") -> N/A
B12: =IFERROR(VLOOKUP(A12,'EMP Employees'!$A:$V,2,0),"") | C12: =IFERROR(VLOOKUP(A12,'EMP Employees'!$A:$V,12,0),"") | D12: =IFERROR(TODAY()-C12,0) -> 0 | E12: =IFERROR(INT(D12/17),0) -> 0 | G12: =IFERROR(E12-F12,0) -> 0 | H12: =IFERROR(SUMIFS('ABS Absence Log'!D:D,'ABS Absence Log'!A:A,A12,'ABS Absence Log'!C:C,"Sick Leave"),0) -> 0 | I12: =IFERROR(SUMIFS('ABS Absence Log'!D:D,'ABS Absence Log'!A:A,A12,'ABS Absence Log'!C:C,"Maternity Leave")+SUMIFS('ABS Absence Log'!D:D,'ABS Absence Log'!A:A,A12,'ABS Absence Log'!C:C,"Paternity Leave"),0) -> 0 | J12: =IFERROR(VLOOKUP(A12,'EMP Employees'!$A:$V,16,0),"") | K12: =IFERROR(VLOOKUP(A12,'EMP Employees'!$A:$V,17,0),"") | L12: =IFERROR(IF(AND(K12<>"",K12<TODAY()),G12,"N/A"),"") -> N/A
B13: =IFERROR(VLOOKUP(A13,'EMP Employees'!$A:$V,2,0),"") | C13: =IFERROR(VLOOKUP(A13,'EMP Employees'!$A:$V,12,0),"") | J13: =IFERROR(VLOOKUP(A13,'EMP Employees'!$A:$V,16,0),"") | K13: =IFERROR(VLOOKUP(A13,'EMP Employees'!$A:$V,17,0),"")
A14: Leave Earned uses contract-type logic (Labour Act Cap 11:11) | Col F (Taken) = editable

Sheet ABS Absence Log
A1: GENESIS HR · ABSENCE & LEAVE LOG
A2: Emp ID | B2: Employee Name | C2: Leave Type | D2: Days | E2: Start Date | F2: End Date | G2: Approved By | H2: Notes

Sheet REC Recruitment
A1: GENESIS HR · RECRUITMENT PIPELINE
A2: Ref No. | B2: Candidate Name | C2: Position Applied | D2: Source | E2: Date Applied | F2: Interview Score (1-5) | G2: Status | H2: Interviewer | I2: Notes | J2: Decision Date | K2: Days in Pipeline | L2: Source Channel
A12: RECRUITMENT METRICS · Key Performance Indicators
A13: Applied | B13: In Progress | C13: Hired | D13: Rejected | E13: Avg Score | F13: Avg Days | G13: Hire Rate
A14: =COUNTIF(G3:G9,"Applied") -> 0 | B14: =COUNTIF(G3:G9,"Interviewed")+COUNTIF(G3:G9,"Technical Assessment")+COUNTIF(G3:G9,"Offer Extended") -> 0 | C14: =COUNTIF(G3:G9,"Hired") -> 0 | D14: =COUNTIF(G3:G9,"Rejected") -> 0 | E14: =IFERROR(ROUND(AVERAGE(F3:F9),1),0) -> 0 | F14: =IFERROR(ROUND(AVERAGE(K3:K9),0),"N/A") -> N/A | G14: =IFERROR(TEXT(COUNTIF(G3:G9,"Hired")/COUNTA(A3:A9),"0%"),"0%") -> 0%
A16: Source | B16: Total | C16: Share % | D16: Hired
A17: LinkedIn | B17: =COUNTIF(D3:D9,"LinkedIn") -> 0 | C17: =IFERROR(TEXT(COUNTIF(D3:D9,"LinkedIn")/COUNTA(A3:A9),"0%"),"") | D17: =COUNTIFS(D3:D9,"LinkedIn",G3:G9,"Hired") -> 0
A18: Referral | B18: =COUNTIF(D3:D9,"Referral") -> 0 | C18: =IFERROR(TEXT(COUNTIF(D3:D9,"Referral")/COUNTA(A3:A9),"0%"),"") | D18: =COUNTIFS(D3:D9,"Referral",G3:G9,"Hired") -> 0
A19: Indeed | B19: =COUNTIF(D3:D9,"Indeed") -> 0 | C19: =IFERROR(TEXT(COUNTIF(D3:D9,"Indeed")/COUNTA(A3:A9),"0%"),"") | D19: =COUNTIFS(D3:D9,"Indeed",G3:G9,"Hired") -> 0
A20: Company Website | B20: =COUNTIF(D3:D9,"Company Website") -> 0 | C20: =IFERROR(TEXT(COUNTIF(D3:D9,"Company Website")/COUNTA(A3:A9),"0%"),"") | D20: =COUNTIFS(D3:D9,"Company Website",G3:G9,"Hired") -> 0
A21: Agency | B21: =COUNTIF(D3:D9,"Agency") -> 0 | C21: =IFERROR(TEXT(COUNTIF(D3:D9,"Agency")/COUNTA(A3:A9),"0%"),"") | D21: =COUNTIFS(D3:D9,"Agency",G3:G9,"Hired") -> 0
A22: Job Board | B22: =COUNTIF(D3:D9,"Job Board") -> 0 | C22: =IFERROR(TEXT(COUNTIF(D3:D9,"Job Board")/COUNTA(A3:A9),"0%"),"") | D22: =COUNTIFS(D3:D9,"Job Board",G3:G9,"Hired") -> 0

Sheet HIST Monthly History
A1: GENESIS HR · MONTHLY PAYROLL HISTORY — Financial Year 2024/2025
A2: YTD Gross in Payroll sheet now references this table — update monthly gross here for accurate year-to-date totals
A3: Emp ID | B3: Full Name | C3: Jan | D3: Feb | E3: Mar | F3: Apr | G3: May | H3: Jun | I3: Jul | J3: Aug | K3: Sep | L3: Oct | M3: Nov | N3: Dec | O3: YTD Gross
B4: =IFERROR(VLOOKUP(A4,'EMP Employees'!$A:$B,2,0),"") | O4: =SUM(C4:N4) -> 0 | P4: =SUM(C4:G4) -> 0
B5: =IFERROR(VLOOKUP(A5,'EMP Employees'!$A:$B,2,0),"") | O5: =SUM(C5:N5) -> 0 | P5: =SUM(C5:G5) -> 0
B6: =IFERROR(VLOOKUP(A6,'EMP Employees'!$A:$B,2,0),"") | O6: =SUM(C6:N6) -> 0 | P6: =SUM(C6:G6) -> 0
B7: =IFERROR(VLOOKUP(A7,'EMP Employees'!$A:$B,2,0),"") | O7: =SUM(C7:N7) -> 0 | P7: =SUM(C7:G7) -> 0
B8: =IFERROR(VLOOKUP(A8,'EMP Employees'!$A:$B,2,0),"") | O8: =SUM(C8:N8) -> 0 | P8: =SUM(C8:G8) -> 0
B9: =IFERROR(VLOOKUP(A9,'EMP Employees'!$A:$B,2,0),"") | O9: =SUM(C9:N9) -> 0 | P9: =SUM(C9:G9) -> 0
B10: =IFERROR(VLOOKUP(A10,'EMP Employees'!$A:$B,2,0),"") | O10: =SUM(C10:N10) -> 0 | P10: =SUM(C10:G10) -> 0
B11: =IFERROR(VLOOKUP(A11,'EMP Employees'!$A:$B,2,0),"") | O11: =SUM(C11:N11) -> 0 | P11: =SUM(C11:G11) -> 0
B12: =IFERROR(VLOOKUP(A12,'EMP Employees'!$A:$B,2,0),"") | O12: =SUM(C12:N12) -> 0 | P12: =SUM(C12:G12) -> 0
B13: =IFERROR(VLOOKUP(A13,'EMP Employees'!$A:$B,2,0),"") | O13: =SUM(C13:N13) -> 0 | P13: =SUM(C13:G13) -> 0
A14: TOTAL | B14: =IFERROR(VLOOKUP(A14,'EMP Employees'!$A:$B,2,0),"") | C14: =SUM(C4:C13) -> 0 | D14: =SUM(D4:D13) -> 0 | E14: =SUM(E4:E13) -> 0 | F14: =SUM(F4:F13) -> 0 | G14: =SUM(G4:G13) -> 0 | H14: =SUM(H4:H13) -> 0 | I14: =SUM(I4:I13) -> 0 | J14: =SUM(J4:J13) -> 0 | ... N14: =SUM(N4:N13) -> 0 | O14: =SUM(C14:N14) -> 0 | P14: =SUM(P4:P13) -> 0
B15: =IFERROR(VLOOKUP(A15,'EMP Employees'!$A:$B,2,0),"") | O15: =SUM(C15:N15) -> 0
A16: Blue (current month) = editable | ⬛ Past months = locked | Grey = future months | YTD = sum of all completed months | B16: =IFERROR(VLOOKUP(A16,'EMP Employees'!$A:$B,2,0),"") | O16: =SUM(C16:N16) -> 0
B17: =IFERROR(VLOOKUP(A17,'EMP Employees'!$A:$B,2,0),"") | O17: =SUM(C17:N17) -> 0
B18: =IFERROR(VLOOKUP(A18,'EMP Employees'!$A:$B,2,0),"") | O18: =SUM(C18:N18) -> 0
B19: =IFERROR(VLOOKUP(A19,'EMP Employees'!$A:$B,2,0),"") | O19: =SUM(C19:N19) -> 0
B20: =IFERROR(VLOOKUP(A20,'EMP Employees'!$A:$B,2,0),"") | O20: =SUM(C20:N20) -> 0

Sheet AUDIT LOG
A1: GENESIS HR · AUDIT LOG — Change History Register
A2: Record every salary or data change here. Required for NamRA audits and Labour Commissioner reviews.
A3: Date | B3: Changed By | C3: Sheet / Module | D3: Emp ID | E3: Field Changed | F3: Previous Value | G3: New Value | H3: Notes / Reason

Sheet SET Settings
A1: GENESIS HR · SETTINGS & GLOBAL PARAMETERS
A2: Namibia | NamRA Compliant | Financial Year 2024/2025
A4: PAYE TAX BRACKETS — NamRA (Annual Income Bands)
A5: Annual Income From (N$) | B5: Annual Income To (N$) | C5: Rate (%) | D5: Fixed Amount (N$) | E5: Band Description
A6: 0 | B6: 50000 | C6: 0 | D6: 0 | E6: Tax-Free Threshold
A7: 50001 | B7: 100000 | C7: 18 | D7: 0 | E7: 18% on amount over N$50,000
A8: 100001 | B8: 300000 | C8: 25 | D8: 9000 | E8: 25% on amount over N$100,000
A9: 300001 | B9: 500000 | C9: 28 | D9: 59000 | E9: 28% on amount over N$300,000
A10: 500001 | B10: 800000 | C10: 30 | D10: 115000 | E10: 30% on amount over N$500,000
A11: 800001 | B11: 1500000 | C11: 32 | D11: 205000 | E11: 32% on amount over N$800,000
A12: 1500001 | B12: 999999999 | C12: 37 | D12: 429000 | E12: 37% on amount over N$1,500,000
A14: SOCIAL SECURITY (SSC) — Namibia Social Security Commission
A15: Parameter | B15: Value | C15: Format | D15: Notes
A16: Employee Contribution Rate | B16: 0.009 | C16: 0.0% | D16: 0.9% of Basic Salary
A17: Employer Contribution Rate | B17: 0.009 | C17: 0.0% | D17: 0.9% of Basic Salary
A18: Monthly Ceiling (Employee) | B18: 81 | C18: "N$"#,##0.00 | D18: Maximum employee deduction
A19: Monthly Ceiling (Employer) | B19: 81 | C19: "N$"#,##0.00 | D19: Maximum employer contribution
A20: Calculation Base | B20: Basic Salary | C20: @ | D20: SSC applies to basic salary only
A22: VET LEVY — Vocational Education & Training
A23: VET Levy Enabled | B23: YES | C23: 1% of Payroll if annual payroll > N$1,000,000
A24: VET Levy Rate | B24: 0.01 | C24: Annual Payroll Threshold | D24: 1000000
A26: LOOKUP LISTS — Named Ranges for Validation | G26: Pay Type
A27: Departments | B27: Job Titles | C27: Contract Types | D27: Leave Types | E27: Gender | F27: Status | G27: Pay Type
A28: Executive | B28: Chief Executive Officer | C28: Permanent | D28: Annual Leave | E28: Male | F28: Active | G28: Hourly
A29: Finance | B29: Chief Financial Officer | C29: Fixed-Term | D29: Sick Leave | E29: Female | F29: On Leave | G29: Monthly
A30: Human Resources | B30: HR Manager | C30: Freelance | D30: Maternity Leave | E30: Non-Binary | F30: Terminated
A31: Operations | B31: Operations Manager | C31: Internship | D31: Paternity Leave | E31: Prefer Not to Say | F31: Suspended
A32: Sales & Marketing | B32: Sales Manager | C32: Probation | D32: Study Leave | F32: Resigned
A33: Information Technology | B33: IT Manager | C33: Casual | D33: Unpaid Leave
A34: Legal & Compliance | B34: Software Developer | D34: Compassionate Leave
A35: Logistics | B35: Accountant | D35: Public Holiday
A36: Customer Service | B36: HR Officer
B37: Admin Officer
B38: Driver
B39: Receptionist
B40: Legal Counsel
B41: Payroll Officer
B42: General Worker
B43: Operator
A67: LABOUR ACT RATE MULTIPLIERS — Sections 29, 32, 33
...
