Workbook

Sheet Settings
A1: SETTINGS & CHART OF ACCOUNTS | Namibia Financial Model
A2: GLOBAL CONSTANTS
A3: Constant | B3: Value | C3: Notes
A4: Corporate Tax Rate | B4: 0.3 | C4: NamRA standard rate
A5: VAT Rate | B5: 0.15 | C5: Namibia VAT
A6: Annual Interest Rate | B6: 0.1 | C6: Applied to Loans Payable balance for Interest Expense
A7: Reporting Period | B7: 31 December 2025 | C7: Reporting date used in all statement headers (input)
A8: Company Name | B8: Company Name (Pty) Ltd | C8: Legal entity name used in all statement headers (input)
A9: Months in Period | B9: 12 | C9: Used to pro-rate interest expense (12 = full year)
A10: CHART OF ACCOUNTS
A11: Account Name | B11: Category | C11: Statement | D11: Normal Balance
A12: Cash & Cash Equivalents | B12: Asset | C12: BS | D12: Debit
A13: Accounts Receivable | B13: Asset | C13: BS | D13: Debit
A14: Inventory | B14: Asset | C14: BS | D14: Debit
A15: Prepaid Expenses | B15: Asset | C15: BS | D15: Debit
A16: Property, Plant & Equipment | B16: Asset | C16: BS | D16: Debit
A17: Accumulated Depreciation | B17: Asset | C17: BS | D17: Credit
A18: Accounts Payable | B18: Liability | C18: BS | D18: Credit
A19: VAT Payable | B19: Liability | C19: BS | D19: Credit
A20: Income Tax Payable | B20: Liability | C20: BS | D20: Credit
A21: Loans Payable | B21: Liability | C21: BS | D21: Credit
A22: Accrued Liabilities | B22: Liability | C22: BS | D22: Credit
... A39: Entertainment (50% Non-Deductible) | B39: Expense | C39: IS | D39: Debit

Sheet KPI Dashboard
A1: =Settings!B8&" | EXECUTIVE KPI DASHBOARD"
A2: =Settings!B7
A4: PROFITABILITY MARGINS
A5: KPI | B5: Formula | C5: Current Period | D5: Prior Period | E5: Trend
A6: Gross Margin | B6: Gross Profit / Revenue | C6: =IFERROR('Income Statement'!C12/'Income Statement'!C7,0) | D6: =IFERROR('Income Statement'!E12/'Income Statement'!E7,0) | E6: =IF(C6<>0,IF(C6>D6,"▲ Improved","▼ Declined"),"-")
A7: EBIT Margin | B7: EBIT / Revenue | C7: =IFERROR('Income Statement'!C25/'Income Statement'!C7,0) | D7: =IFERROR('Income Statement'!E25/'Income Statement'!E7,0) | E7: =IF(C7<>0,IF(C7>D7,"▲ Improved","▼ Declined"),"-")
A8: Net Profit Margin | B8: NPAT / Revenue | C8: =IFERROR('Income Statement'!C31/'Income Statement'!C7,0) | D8: =IFERROR('Income Statement'!E31/'Income Statement'!E7,0) | E8: =IF(C8<>0,IF(C8>D8,"▲ Improved","▼ Declined"),"-")
A10: LIQUIDITY & SOLVENCY
A11: KPI | B11: Formula | C11: Current Period | D11: Benchmark | E11: Status
A12: Current Ratio | B12: Current Assets / Current Liabilities | C12: =IFERROR('Balance Sheet'!C10/'Balance Sheet'!C23,0) | D12: >2.0 | E12: =IF(C12<>0,"↗ See details","-")
A13: Debt-to-Equity | B13: Total Liabilities / Total Equity | C13: =IFERROR('Balance Sheet'!C27/'Balance Sheet'!C34,0) | D13: <1.0 | E13: =IF(C13<>0,"↗ See details","-")
A14: Interest Coverage | B14: EBIT / Interest Expense | C14: =IFERROR('Income Statement'!C25/'Income Statement'!C27,0) | D14: >3.0 | E14: =IF(C14<>0,"↗ See details","-")
A15: Return on Equity | B15: NPAT / Total Equity | C15: =IFERROR('Income Statement'!C31/'Balance Sheet'!C34,0) | D15: >15% | E15: =IF(C15<>0,"↗ See details","-")
A17: KEY FINANCIAL FIGURES (NAD)
A18: Metric | C18: Current Period | D18: Prior Period | E18: Change %
A19: Total Revenue | C19: ='Income Statement'!C7 | D19: ='Income Statement'!E7 | E19: =IFERROR((C19-D19)/ABS(D19),0)
A20: Gross Profit | C20: ='Income Statement'!C12 | D20: ='Income Statement'!E12 | E20: =IFERROR((C20-D20)/ABS(D20),0)
A21: EBIT | C21: ='Income Statement'!C25 | D21: ='Income Statement'!E25 | E21: =IFERROR((C21-D21)/ABS(D21),0)
A22: Net Profit After Tax | C22: ='Income Statement'!C31 | D22: ='Income Statement'!E31 | E22: =IFERROR((C22-D22)/ABS(D22),0)
A23: Total Assets | C23: ='Balance Sheet'!C15
A24: Total Equity | C24: ='Balance Sheet'!C34
A26: All figures in NAD. Prior Period column populates from 'Prior Period (NAD)' column in Income Statement.

Sheet Prior Year
A1: PRIOR YEAR CLOSING BALANCES | feeds comparatives & opening balances
A2: Enter the audited closing balances of the previous financial year ONCE. Everything else flows automatically.
A3: Item | B3: Closing balance (N$) | C3: Feeds into
A4: Cash & cash equivalents | B4: 0 | C4: Cash Flow opening cash; AFS Position comparative
A5: Accounts receivable | B5: 0 | C5: Cash Flow working capital; AFS Position comparative
A6: Inventory | B6: 0 | C6: Cash Flow working capital; AFS Position comparative
A7: Prepaid expenses | B7: 0 | C7: Cash Flow working capital; AFS Position comparative
A8: Property, plant & equipment (cost) | B8: 0 | C8: AFS Position comparative
A9: Accumulated depreciation (enter as negative) | B9: 0 | C9: AFS Position comparative
A10: Accounts payable | B10: 0 | C10: Cash Flow working capital; AFS Position comparative
A11: VAT payable | B11: 0 | C11: Cash Flow working capital; AFS Position comparative
A12: Income tax payable | B12: 0 | C12: AFS Position comparative
A13: Accrued liabilities | B13: 0 | C13: Cash Flow working capital; AFS Position comparative
A14: Loans payable (long-term) | B14: 0 | C14: AFS Position comparative
A15: Share capital | B15: 0 | C15: Statement of Changes in Equity (opening)
A16: Retained earnings (closing prior year) | B16: 0 | C16: Balance Sheet & Equity statement (opening)
A17: Total assets | B17: =SUM(B4:B9)
A18: Total liabilities | B18: =SUM(B10:B14)
A19: Total equity | B19: =B15+B16
A20: PRIOR YEAR BALANCE CHECK (must be 0) | B20: =B17-B18-B19

Sheet Journal
A1: GENERAL JOURNAL | Double-Entry Transaction Register
A2: DOUBLE-ENTRY CHECK (Total Debits − Total Credits, must be 0): | D2: =SUM(D4:D103)-SUM(E4:E103) | E2: Every transaction needs a debit line and a credit line of equal amounts.
A3: Date | B3: Description | C3: Account (dropdown) | D3: Debit (NAD) | E3: Credit (NAD) | F3: VAT (Y/N) | G3: VAT Amount (NAD) | H3: Net Amount (NAD)
G4: =IF(F4="Y",(D4+E4)*Settings!$B$5/(1+Settings!$B$5),0) | H4: =(D4+E4)-G4
G5: =IF(F5="Y",(D5+E5)*Settings!$B$5/(1+Settings!$B$5),0) | H5: =(D5+E5)-G5
G6: =IF(F6="Y",(D6+E6)*Settings!$B$5/(1+Settings!$B$5),0) | H6: =(D6+E6)-G6
G7: =IF(F7="Y",(D7+E7)*Settings!$B$5/(1+Settings!$B$5),0) | H7: =(D7+E7)-G7
G8: =IF(F8="Y",(D8+E8)*Settings!$B$5/(1+Settings!$B$5),0) | H8: =(D8+E8)-G8
G9: =IF(F9="Y",(D9+E9)*Settings!$B$5/(1+Settings!$B$5),0) | H9: =(D9+E9)-G9
G10: =IF(F10="Y",(D10+E10)*Settings!$B$5/(1+Settings!$B$5),0) | H10: =(D10+E10)-G10
G11: =IF(F11="Y",(D11+E11)*Settings!$B$5/(1+Settings!$B$5),0) | H11: =(D11+E11)-G11
G12: =IF(F12="Y",(D12+E12)*Settings!$B$5/(1+Settings!$B$5),0) | H12: =(D12+E12)-G12
G13: =IF(F13="Y",(D13+E13)*Settings!$B$5/(1+Settings!$B$5),0) | H13: =(D13+E13)-G13
G14: =IF(F14="Y",(D14+E14)*Settings!$B$5/(1+Settings!$B$5),0) | H14: =(D14+E14)-G14
G15: =IF(F15="Y",(D15+E15)*Settings!$B$5/(1+Settings!$B$5),0) | H15: =(D15+E15)-G15
... G103: =IF(F103="Y",(D103+E103)*Settings!$B$5/(1+Settings!$B$5),0) | H103: =(D103+E103)-G103
A104: TOTALS | D104: =SUM(D4:D103) | E104: =SUM(E4:E103) | G104: =SUM(G4:G103) | H104: =SUM(H4:H103)
A106: Dates as DD/MM/YYYY. Amounts entered VAT-inclusive; VAT extracted automatically when flag = Y.

Sheet Trial Balance
A1: =Settings!B8&" | TRIAL BALANCE | Balancete | "&Settings!B7
A2: Auto-generated from the General Journal. Debits must equal Credits. | D2: DIFFERENCE (must be 0): | E2: =D32-E32
A3: # | B3: Account | C3: Category | D3: Debit (NAD) | E3: Credit (NAD) | F3: Statement
A4: 1 | B4: =Settings!A12 | C4: =Settings!B12 | D4: =MAX(0,SUMIF(Journal!$C:$C,$B4,Journal!$D:$D)-SUMIF(Journal!$C:$C,$B4,Journal!$E:$E)) | E4: =MAX(0,SUMIF(Journal!$C:$C,$B4,Journal!$E:$E)-SUMIF(Journal!$C:$C,$B4,Journal!$D:$D)) | F4: =Settings!C12
A5: 2 | B5: =Settings!A13 | C5: =Settings!B13 | D5: =MAX(0,SUMIF(Journal!$C:$C,$B5,Journal!$D:$D)-SUMIF(Journal!$C:$C,$B5,Journal!$E:$E)) | E5: =MAX(0,SUMIF(Journal!$C:$C,$B5,Journal!$E:$E)-SUMIF(Journal!$C:$C,$B5,Journal!$D:$D)) | F5: =Settings!C13
A6: 3 | B6: =Settings!A14 | C6: =Settings!B14 | D6: =MAX(0,SUMIF(Journal!$C:$C,$B6,Journal!$D:$D)-SUMIF(Journal!$C:$C,$B6,Journal!$E:$E)) | E6: =MAX(0,SUMIF(Journal!$C:$C,$B6,Journal!$E:$E)-SUMIF(Journal!$C:$C,$B6,Journal!$D:$D)) | F6: =Settings!C14
A7: 4 | B7: =Settings!A15 | C7: =Settings!B15 | D7: =MAX(0,SUMIF(Journal!$C:$C,$B7,Journal!$D:$D)-SUMIF(Journal!$C:$C,$B7,Journal!$E:$E)) | E7: =MAX(0,SUMIF(Journal!$C:$C,$B7,Journal!$E:$E)-SUMIF(Journal!$C:$C,$B7,Journal!$D:$D)) | F7: =Settings!C15
A8: 5 | B8: =Settings!A16 | C8: =Settings!B16 | D8: =MAX(0,SUMIF(Journal!$C:$C,$B8,Journal!$D:$D)-SUMIF(Journal!$C:$C,$B8,Journal!$E:$E)) | E8: =MAX(0,SUMIF(Journal!$C:$C,$B8,Journal!$E:$E)-SUMIF(Journal!$C:$C,$B8,Journal!$D:$D)) | F8: =Settings!C16
A9: 6 | B9: =Settings!A17 | C9: =Settings!B17 | D9: =MAX(0,SUMIF(Journal!$C:$C,$B9,Journal!$D:$D)-SUMIF(Journal!$C:$C,$B9,Journal!$E:$E)) | E9: =MAX(0,SUMIF(Journal!$C:$C,$B9,Journal!$E:$E)-SUMIF(Journal!$C:$C,$B9,Journal!$D:$D)) | F9: =Settings!C17
A10: 7 | B10: =Settings!A18 | C10: =Settings!B18 | D10: =MAX(0,SUMIF(Journal!$C:$C,$B10,Journal!$D:$D)-SUMIF(Journal!$C:$C,$B10,Journal!$E:$E)) | E10: =MAX(0,SUMIF(Journal!$C:$C,$B10,Journal!$E:$E)-SUMIF(Journal!$C:$C,$B10,Journal!$D:$D)) | F10: =Settings!C18
A11: 8 | B11: =Settings!A19 | C11: =Settings!B19 | D11: =MAX(0,SUMIF(Journal!$C:$C,$B11,Journal!$D:$D)-SUMIF(Journal!$C:$C,$B11,Journal!$E:$E)) | E11: =MAX(0,SUMIF(Journal!$C:$C,$B11,Journal!$E:$E)-SUMIF(Journal!$C:$C,$B11,Journal!$D:$D)) | F11: =Settings!C19
A12: 9 | B12: =Settings!A20 | C12: =Settings!B20 | D12: =MAX(0,SUMIF(Journal!$C:$C,$B12,Journal!$D:$D)-SUMIF(Journal!$C:$C,$B12,Journal!$E:$E)) | E12: =MAX(0,SUMIF(Journal!$C:$C,$B12,Journal!$E:$E)-SUMIF(Journal!$C:$C,$B12,Journal!$D:$D)) | F12: =Settings!C20
A13: 10 | B13: =Settings!A21 | C13: =Settings!B21 | D13: =MAX(0,SUMIF(Journal!$C:$C,$B13,Journal!$D:$D)-SUMIF(Journal!$C:$C,$B13,Journal!$E:$E)) | E13: =MAX(0,SUMIF(Journal!$C:$C,$B13,Journal!$E:$E)-SUMIF(Journal!$C:$C,$B13,Journal!$D:$D)) | F13: =Settings!C21
A14: 11 | B14: =Settings!A22 | C14: =Settings!B22 | D14: =MAX(0,SUMIF(Journal!$C:$C,$B14,Journal!$D:$D)-SUMIF(Journal!$C:$C,$B14,Journal!$E:$E)) | E14: =MAX(0,SUMIF(Journal!$C:$C,$B14,Journal!$E:$E)-SUMIF(Journal!$C:$C,$B14,Journal!$D:$D)) | F14: =Settings!C22
A15: 12 | B15: =Settings!A23 | C15: =Settings!B23 | D15: =MAX(0,SUMIF(Journal!$C:$C,$B15,Journal!$D:$D)-SUMIF(Journal!$C:$C,$B15,Journal!$E:$E)) | E15: =MAX(0,SUMIF(Journal!$C:$C,$B15,Journal!$E:$E)-SUMIF(Journal!$C:$C,$B15,Journal!$D:$D)) | F15: =Settings!C23
... A31: 28 | B31: =Settings!A39 | C31: =Settings!B39 | D31: =MAX(0,SUMIF(Journal!$C:$C,$B31,Journal!$D:$D)-SUMIF(Journal!$C:$C,$B31,Journal!$E:$E)) | E31: =MAX(0,SUMIF(Journal!$C:$C,$B31,Journal!$E:$E)-SUMIF(Journal!$C:$C,$B31,Journal!$D:$D)) | F31: =Settings!C39
B32: TOTAL | D32: =SUM(D4:D31) | E32: =SUM(E4:E31)
B34: =IF(D32=E32,"BALANCED ✓ Total Debits = Total Credits","OUT OF BALANCE ✗ Check the Journal — every entry needs equal debit & credit")

Sheet Income Statement
A1: =Settings!B8&" | INCOME STATEMENT (DRE) | For the Period Ended "&Settings!B7 | E1: Prior Period (NAD) | F1: Variation %
A2: Line Item | B2: Account | C2: NAD | D2: Notes | E2: Prior Period (NAD) | F2: Var %
A3: REVENUE
A4: Sales Revenue | B4: Sales Revenue | C4: =SUMIF(Journal!$C:$C,"Sales Revenue",Journal!$E:$E)-SUMIF(Journal!$C:$C,"Sales Revenue",Journal!$D:$D) | E4: 0 | F4: =IF(E4<>0,(C4-E4)/ABS(E4),IF(C4<>0,1,0))
A5: Service Revenue | B5: Service Revenue | C5: =SUMIF(Journal!$C:$C,"Service Revenue",Journal!$E:$E)-SUMIF(Journal!$C:$C,"Service Revenue",Journal!$D:$D) | E5: 0 | F5: =IF(E5<>0,(C5-E5)/ABS(E5),IF(C5<>0,1,0))
A6: Other Income | B6: Other Income | C6: =SUMIF(Journal!$C:$C,"Other Income",Journal!$E:$E)-SUMIF(Journal!$C:$C,"Other Income",Journal!$D:$D) | E6: 0 | F6: =IF(E6<>0,(C6-E6)/ABS(E6),IF(C6<>0,1,0))
A7: GROSS REVENUE | C7: =SUM(C4:C6) | E7: 0 | F7: =IF(E7<>0,(C7-E7)/ABS(E7),IF(C7<>0,1,0))
A8: COST OF GOODS SOLD (COGS) | E8: 0
A9: Cost of Goods Sold | B9: Cost of Goods Sold | C9: =SUMIF(Journal!$C:$C,"Cost of Goods Sold",Journal!$D:$D)-SUMIF(Journal!$C:$C,"Cost of Goods Sold",Journal!$E:$E) | E9: 0 | F9: =IF(E9<>0,(C9-E9)/ABS(E9),IF(C9<>0,1,0))
A10: Direct Labour | B10: Direct Labour | C10: =SUMIF(Journal!$C:$C,"Direct Labour",Journal!$D:$D)-SUMIF(Journal!$C:$C,"Direct Labour",Journal!$E:$E) | E10: 0 | F10: =IF(E10<>0,(C10-E10)/ABS(E10),IF(C10<>0,1,0))
A11: TOTAL COGS | C11: =SUM(C9:C10) | E11: 0 | F11: =IF(E11<>0,(C11-E11)/ABS(E11),IF(C11<>0,1,0))
A12: GROSS PROFIT | C12: =C7-C11 | E12: 0 | F12: =IF(E12<>0,(C12-E12)/ABS(E12),IF(C12<>0,1,0))
A13: OPERATING EXPENSES (OPEX) | E13: 0
A14: Salaries & Wages | B14: Salaries & Wages | C14: =SUMIF(Journal!$C:$C,"Salaries & Wages",Journal!$D:$D)-SUMIF(Journal!$C:$C,"Salaries & Wages",Journal!$E:$E) | E14: 0 | F14: =IF(E14<>0,(C14-E14)/ABS(E14),IF(C14<>0,1,0))
A15: Rent Expense | B15: Rent Expense | C15: =SUMIF(Journal!$C:$C,"Rent Expense",Journal!$D:$D)-SUMIF(Journal!$C:$C,"Rent Expense",Journal!$E:$E) | E15: 0 | F15: =IF(E15<>0,(C15-E15)/ABS(E15),IF(C15<>0,1,0))
A16: Utilities Expense | B16: Utilities Expense | C16: =SUMIF(Journal!$C:$C,"Utilities Expense",Journal!$D:$D)-SUMIF(Journal!$C:$C,"Utilities Expense",Journal!$E:$E) | E16: 0 | F16: =IF(E16<>0,(C16-E16)/ABS(E16),IF(C16<>0,1,0))
A17: Marketing & Advertising | B17: Marketing & Advertising | C17: =SUMIF(Journal!$C:$C,"Marketing & Advertising",Journal!$D:$D)-SUMIF(Journal!$C:$C,"Marketing & Advertising",Journal!$E:$E) | E17: 0 | F17: =IF(E17<>0,(C17-E17)/ABS(E17),IF(C17<>0,1,0))
A18: Depreciation Expense | B18: Depreciation Expense | C18: =SUMIF(Journal!$C:$C,"Depreciation Expense",Journal!$D:$D)-SUMIF(Journal!$C:$C,"Depreciation Expense",Journal!$E:$E) | E18: 0 | F18: =IF(E18<>0,(C18-E18)/ABS(E18),IF(C18<>0,1,0))
A19: Travel & Entertainment | B19: Travel & Entertainment | C19: =SUMIF(Journal!$C:$C,"Travel & Entertainment",Journal!$D:$D)-SUMIF(Journal!$C:$C,"Travel & Entertainment",Journal!$E:$E) | E19: 0 | F19: =IF(E19<>0,(C19-E19)/ABS(E19),IF(C19<>0,1,0))
A20: Professional Fees | B20: Professional Fees | C20: =SUMIF(Journal!$C:$C,"Professional Fees",Journal!$D:$D)-SUMIF(Journal!$C:$C,"Professional Fees",Journal!$E:$E) | E20: 0 | F20: =IF(E20<>0,(C20-E20)/ABS(E20),IF(C20<>0,1,0))
A21: Bank Charges | B21: Bank Charges | C21: =SUMIF(Journal!$C:$C,"Bank Charges",Journal!$D:$D)-SUMIF(Journal!$C:$C,"Bank Charges",Journal!$E:$E) | E21: 0 | F21: =IF(E21<>0,(C21-E21)/ABS(E21),IF(C21<>0,1,0))
A22: Fines & Penalties | B22: Fines & Penalties (Non-Deductible) | C22: =SUMIF(Journal!$C:$C,"Fines & Penalties (Non-Deductible)",Journal!$D:$D)-SUMIF(Journal!$C:$C,"Fines & Penalties (Non-Deductible)",Journal!$E:$E) | E22: 0 | F22: =IF(E22<>0,(C22-E22)/ABS(E22),IF(C22<>0,1,0))
A23: Entertainment (50%) | B23: Entertainment (50% Non-Deductible) | C23: =SUMIF(Journal!$C:$C,"Entertainment (50% Non-Deductible)",Journal!$D:$D)-SUMIF(Journal!$C:$C,"Entertainment (50% Non-Deductible)",Journal!$E:$E) | E23: 0 | F23: =IF(E23<>0,(C23-E23)/ABS(E23),IF(C23<>0,1,0))
A24: TOTAL OPERATING EXPENSES | C24: =SUM(C14:C23) | E24: 0 | F24: =IF(E24<>0,(C24-E24)/ABS(E24),IF(C24<>0,1,0))
A25: OPERATING PROFIT (EBIT) | C25: =C12-C24 | E25: 0 | F25: =IF(E25<>0,(C25-E25)/ABS(E25),IF(C25<>0,1,0))
A26: FINANCE COSTS | E26: 0
A27: Interest Expense | B27: Interest Expense | C27: =(SUMIF(Journal!$C:$C,"Loans Payable",Journal!$E:$E)-SUMIF(Journal!$C:$C,"Loans Payable",Journal!$D:$D))*Settings!B6*Settings!B9/12 | D27: Auto: Loans balance × rate × months/12 (Settings) | E27: 0
A28: NET PROFIT BEFORE TAX (EBT) | C28: =C25-C27 | E28: 0 | F28: =IF(E28<>0,(C28-E28)/ABS(E28),IF(C28<>0,1,0))
A29: Income Tax (see Tax Engine) | C29: ='Tax Engine'!C30 | E29: 0 | F29: =IF(E29<>0,(C29-E29)/ABS(E29),IF(C29<>0,1,0))
A30: Dividends Declared | B30: Manual input / Board resolution | C30: 0 | D30: Enter dividends declared during period
A31: NET PROFIT AFTER TAX | C31: =C28-C29 | F31: =IF(E31<>0,(C31-E31)/ABS(E31),IF(C31<>0,1,0))

Sheet Tax Engine
A1: NAMIBIA TAX ENGINE (NamRA) | Income Tax & Provisional Tax Tracker
A2: Payment | B2: Due Date | C2: Amount (NAD) | D2: Status
A3: STEP 1 – ACCOUNTING PROFIT
A4: Earnings Before Tax (EBT) | B4: From Income Statement | C4: ='Income Statement'!C28 | D4: IS tab
A6: STEP 2 – TAX ADD-BACKS (Non-Deductible Expenses)
A7: Fines & Penalties (Traffic/Regulatory) | B7: S17(1) ITA | C7: =SUMIF(Journal!$C:$C,"Fines & Penalties (Non-Deductible)",Journal!$D:$D)-SUMIF(Journal!$C:$C,"Fines & Penalties (Non-Deductible)",Journal!$E:$E) | D7: Auto – Journal
A8: 50% Disallowance – Entertainment | B8: S17(1)(f) ITA | C8: =(SUMIF(Journal!$C:$C,"Entertainment (50% Non-Deductible)",Journal!$D:$D)-SUMIF(Journal!$C:$C,"Entertainment (50% Non-Deductible)",Journal!$E:$E))*0.5 | D8: Auto – Journal (50% of total)
A9: Other Non-Deductible Items | B9: Manual input | C9: 0 | D9: Enter amount
A10: TOTAL ADD-BACKS | C10: =SUM(C7:C9)
A12: STEP 3 – CAPITAL ALLOWANCES (Wear & Tear)
A13: Note: NamRA Schedule – Computers 33%, Vehicles 20%, Plant 10%, Buildings 4%
A14: PP&E – Computers & Equipment (33.33% p.a.) | B14: S17B ITA | C14: ='Asset Register'!B33 | D14: Auto – Asset Register
A15: PP&E – Motor Vehicles (20% p.a.) | B15: S17B ITA | C15: ='Asset Register'!B34 | D15: Auto – Asset Register
A16: PP&E – Plant & Machinery (10% p.a.) | B16: S17B ITA | C16: ='Asset Register'!B35 | D16: Auto – Asset Register
A17: Industrial Buildings (4% p.a.) | B17: S17C ITA | C17: ='Asset Register'!B36 | D17: Auto – Asset Register
A18: TOTAL CAPITAL ALLOWANCES | C18: =SUM(C14:C17)
A20: STEP 4 – TAXABLE INCOME COMPUTATION
A21: Accounting Profit (EBT) | B21: Step 1 | C21: =C4 | D21: Step 1
A22: Add: Non-Deductible Expenses | B22: Step 2 | C22: =C10 | D22: Step 2
A23: Less: Capital Allowances | B23: Step 3 | C23: =-C18 | D23: Step 3
A24: Less: Assessed loss brought forward | B24: Manual input – prior year assessment | C24: 0 | D24: NamRA: losses carried forward indefinitely
A25: TAXABLE INCOME | C25: =MAX(0,C21+C22+C23-C24)
A27: STEP 5 – INCOME TAX LIABILITY
A28: Taxable Income | B28: Step 4 | C28: =C25 | D28: Step 4
A29: Corporate Tax Rate | B29: Settings | C29: =Settings!B4 | D29: Settings
A30: INCOME TAX LIABILITY | C30: =C25*C29
A32: STEP 6 – PROVISIONAL TAX TRACKER (NamRA Two-Payment System)
A33: Note: P1 = 40% estimated (August); P2 = 60% balance (February)
A34: 1st Provisional Payment (P1) | B34: August – 40% of estimated tax | C34: =C30*0.4 | D34: Auto-calculated
A35: 2nd Provisional Payment (P2) | B35: February – Balancing payment | C35: =C30*0.6 | D35: Auto-calculated
A36: Total Provisional Tax Paid | C36: =SUM(C34:C35)
A37: Tax Still Payable / (Refundable) | C37: =C30-C36 | D37: Remaining liability
A39: Assessed loss carried forward to next year | B39: Auto-calculated | C39: =MAX(0,-(C21+C22+C23-C24)) | D39: Enter in C24 next year

Sheet Balance Sheet
A1: =Settings!B8&" | BALANCE SHEET | Statement of Financial Position | "&Settings!B7
A2: BALANCE CHECK (Assets – Liabilities – Equity, should = 0): | C2: =C15-(C27+C34)
A3: Line Item | B3: Account / Notes | C3: NAD
A4: ASSETS
A5: Current Assets
A6: Cash & Cash Equivalents | B6: Journal – Cash account | C6: =SUMIF(Journal!$C:$C,"Cash & Cash Equivalents",Journal!$D:$D)-SUMIF(Journal!$C:$C,"Cash & Cash Equivalents",Journal!$E:$E)
A7: Accounts Receivable | B7: Journal – AR balance | C7: =SUMIF(Journal!$C:$C,"Accounts Receivable",Journal!$D:$D)-SUMIF(Journal!$C:$C,"Accounts Receivable",Journal!$E:$E)
A8: Inventory | B8: Journal – Inventory | C8: =SUMIF(Journal!$C:$C,"Inventory",Journal!$D:$D)-SUMIF(Journal!$C:$C,"Inventory",Journal!$E:$E)
A9: Prepaid Expenses | B9: Journal – Prepaid | C9: =SUMIF(Journal!$C:$C,"Prepaid Expenses",Journal!$D:$D)-SUMIF(Journal!$C:$C,"Prepaid Expenses",Journal!$E:$E)
A10: Total Current Assets | C10: =SUM(C6:C9)
A11: Non-Current Assets
A12: Property, Plant & Equipment (Cost) | B12: Journal – PP&E | C12: =SUMIF(Journal!$C:$C,"Property, Plant & Equipment",Journal!$D:$D)-SUMIF(Journal!$C:$C,"Property, Plant & Equipment",Journal!$E:$E)
A13: Accumulated Depreciation | B13: Journal – Acc. Dep. | C13: =SUMIF(Journal!$C:$C,"Accumulated Depreciation",Journal!$D:$D)-SUMIF(Journal!$C:$C,"Accumulated Depreciation",Journal!$E:$E)
A14: Total Non-Current Assets | C14: =SUM(C12:C13)
A15: TOTAL ASSETS | C15: =C10+C14
A17: LIABILITIES
A18: Current Liabilities
A19: Accounts Payable | B19: Journal – AP | C19: =SUMIF(Journal!$C:$C,"Accounts Payable",Journal!$E:$E)-SUMIF(Journal!$C:$C,"Accounts Payable",Journal!$D:$D)
A20: VAT Payable | B20: VAT Ledger – Net Payable | C20: ='VAT Ledger'!F64
A21: Income Tax Payable | B21: Tax Engine – Step 5 | C21: ='Tax Engine'!C30
A22: Accrued Liabilities | B22: Journal – Accruals | C22: =SUMIF(Journal!$C:$C,"Accrued Liabilities",Journal!$E:$E)-SUMIF(Journal!$C:$C,"Accrued Liabilities",Journal!$D:$D)
A23: Total Current Liabilities | C23: =SUM(C19:C22)
A24: Non-Current Liabilities
A25: Loans Payable (Long-term) | B25: Journal – Loans | C25: =SUMIF(Journal!$C:$C,"Loans Payable",Journal!$E:$E)-SUMIF(Journal!$C:$C,"Loans Payable",Journal!$D:$D)
A26: Total Non-Current Liabilities | C26: =C25
A27: TOTAL LIABILITIES | C27: =C23+C26
A29: EQUITY
A30: Share Capital | B30: Journal – Share Capital | C30: =SUMIF(Journal!$C:$C,"Share Capital",Journal!$E:$E)-SUMIF(Journal!$C:$C,"Share Capital",Journal!$D:$D)
A31: Prior Year Retained Earnings | B31: Auto: Prior Year sheet | C31: ='Prior Year'!B16
A32: Less: Dividends Declared | B32: Income Statement | C32: =-'Income Statement'!C30
A33: Current Year Net Profit (After Tax) | B33: Income Statement | C33: ='Income Statement'!C31
A34: TOTAL EQUITY | C34: =SUM(C30:C33)
A35: TOTAL LIABILITIES + EQUITY | C35: =C27+C34

Sheet Cash Flow
A1: =Settings!B8&" | STATEMENT OF CASH FLOWS | For the Period Ended "&Settings!B7
A2: Description | B2: Notes | C2: NAD
A3: OPERATING ACTIVITIES
A4: Net Profit After Tax | B4: From Income Statement | C4: ='Income Statement'!C31
A5: Adjustments for Non-Cash Items
A6: Add: Depreciation Expense | B6: Non-cash charge | C6: ='Income Statement'!C18
A7: Add: Amortisation | B7: If applicable | C7: 0
A8: Changes in Working Capital
A9: (Increase)/Decrease in Accounts Receivable | B9: AR movement | C9: =C43-'Balance Sheet'!C7
A10: (Increase)/Decrease in Inventory | B10: Inventory | C10: =C44-'Balance Sheet'!C8
A11: (Increase)/Decrease in Prepaid Expenses | B11: Prepaid | C11: =C45-'Balance Sheet'!C9
A12: Increase/(Decrease) in Accounts Payable | B12: AP movement | C12: ='Balance Sheet'!C19-C46
A13: Increase/(Decrease) in VAT Payable | B13: VAT | C13: ='Balance Sheet'!C20-C47
A14: Increase/(Decrease) in Accrued Liabilities | B14: Accruals | C14: ='Balance Sheet'!C22-C48
A15: Increase/(Decrease) in Income Tax Payable | B15: Auto: tax accrued, not yet paid | C15: ='Balance Sheet'!C21-'Prior Year'!B12
A16: NET CASH FROM OPERATING ACTIVITIES | C16: =C4+SUM(C6:C7)+SUM(C9:C15)
A18: INVESTING ACTIVITIES
A19: Purchase of PP&E | B19: Auto: Journal – net PP&E additions | C19: =-(SUMIF(Journal!$C:$C,"Property, Plant & Equipment",Journal!$D:$D)-SUMIF(Journal!$C:$C,"Property, Plant & Equipment",Journal!$E:$E))
A20: Proceeds from Disposal of Assets | B20: If applicable | C20: 0
A21: Purchase of Investments | B21: If applicable | C21: 0
A22: NET CASH FROM INVESTING ACTIVITIES | C22: =SUM(C19:C21)
A24: FINANCING ACTIVITIES
A25: Proceeds from Share Capital Issuance | B25: Auto: Journal – credits to Share Capital | C25: =SUMIF(Journal!$C:$C,"Share Capital",Journal!$E:$E)
A26: Repayment of Loans | B26: Auto: Journal – debits to Loans Payable (repayments) | C26: =-SUMIF(Journal!$C:$C,"Loans Payable",Journal!$D:$D)
A27: Dividends Paid | B27: Auto: dividends declared (Income Statement) | C27: =-'Income Statement'!C30
A28: Proceeds from New Borrowings | B28: Auto: Journal – credits to Loans Payable (new borrowings) | C28: =SUMIF(Journal!$C:$C,"Loans Payable",Journal!$E:$E)
A29: NET CASH FROM FINANCING ACTIVITIES | C29: =SUM(C25:C28)
A31: CASH POSITION SUMMARY
A32: Opening Cash Balance | B32: Auto: Prior Year sheet – closing cash | C32: ='Prior Year'!B4
A33: Net Increase / (Decrease) in Cash | C33: =C16+C22+C29
A34: CLOSING CASH BALANCE | C34: =C32+C33
A36: Cross-Check: Cash per Balance Sheet | C36: ='Balance Sheet'!C6 | D36: =C34-C36
A38: Operating | B38: =C16
A39: Investing | B39: =C22
A40: Financing | B40: =C29
A42: OPENING BALANCES (enter prior period closing balances)
A43: Accounts Receivable (opening) | B43: Auto: Prior Year sheet | C43: ='Prior Year'!B5
A44: Inventory (opening) | B44: Auto: Prior Year sheet | C44: ='Prior Year'!B6
A45: Prepaid Expenses (opening) | B45: Auto: Prior Year sheet | C45: ='Prior Year'!B7
A46: Accounts Payable (opening) | B46: Auto: Prior Year sheet | C46: ='Prior Year'!B10
...

Sheet Bank Reconciliation
A1: =Settings!B8&" | BANK RECONCILIATION | Reconciliação Bancária | "&Settings!B7
A2: Yellow cells = manual input (from your bank statement). Green = auto from Journal. The reconciliation must end at a difference of 0.
A4: A — BALANCE PER CASH BOOK (automatic)
A5: 1 | B5: Cash & cash equivalents per General Journal | C5: =SUMIF(Journal!$C:$C,"Cash & Cash Equivalents",Journal!$D:$D)-SUMIF(Journal!$C:$C,"Cash & Cash Equivalents",Journal!$E:$E) | D5: Auto: total debits − credits on the Cash account
A7: B — ADJUSTMENTS TO CASH BOOK (items on the bank statement not yet in your Journal)
A8: 1 | B8: Add: Interest / credits received (not yet booked) | C8: 0 | D8: Enter as positive to add, negative to subtract
A9: 2 | B9: Less: Bank charges / debit orders (not yet booked) | C9: 0 | D9: Enter as positive to add, negative to subtract
A10: 3 | B10: Less: Dishonoured (bounced) cheques | C10: 0 | D10: Enter as positive to add, negative to subtract
A11: 4 | B11: +/- Other corrections to the cash book | C11: 0 | D11: Enter as positive to add, negative to subtract
B12: ADJUSTED CASH BOOK BALANCE | C12: =C5+SUM(C8:C11)
A14: C — BALANCE PER BANK STATEMENT (from your bank)
A15: 1 | B15: Closing balance per bank statement | C15: 0 | D15: Copy the closing balance from your bank statement
A17: D — TIMING DIFFERENCES (recorded in your books but not yet on the bank statement)
A18: 1 | B18: Add: Deposits in transit (banked, not yet cleared) | C18: 0 | D18: Enter as positive to add, negative to subtract
A19: 2 | B19: Less: Unpresented (outstanding) cheques | C19: 0 | D19: Enter as positive to add, negative to subtract
A20: 3 | B20: +/- Bank errors to be corrected | C20: 0 | D20: Enter as positive to add, negative to subtract
B21: ADJUSTED BANK STATEMENT BALANCE | C21: =C15+SUM(C18:C20)
A23: DIFFERENCE (Adjusted Cash Book − Adjusted Bank) must = 0 | C23: =C12-C21
A24: =IF(ROUND(C12-C21,2)=0,"RECONCILED ✓ Cash book agrees with the bank","NOT RECONCILED ✗ Investigate the difference above")

Sheet Asset Register
A1: FIXED ASSET REGISTER & DEPRECIATION SCHEDULE | NamRA Wear & Tear Rates
A2: Blue = manual input | Black = formula | Depreciation Method: Straight-Line | Source: S17B & S17C Income Tax Act
A3: Asset ID | B3: Asset Description | C3: Category | D3: Date Acquired | E3: Cost (NAD) | F3: Useful Life (yrs) | G3: NamRA Rate (%) | H3: Annual Depreciation (NAD) | I3: Acc. Dep. (NAD) | J3: Net Book Value (NAD) | K3: Disposal Date | L3: Notes
A4: Enter each fixed asset below. Annual Depreciation and NBV are auto-calculated. NamRA Rates: Computers 33.33% | Motor Vehicles 20% | Plant & Machinery 10% | Buildings 4%
A5: FA-001 | H5: =IF(E5>0, E5*G5, 0) | I5: =IF(E5>0, H5*1, 0) | J5: =IF(E5>0, E5-I5, 0)
A6: FA-002 | H6: =IF(E6>0, E6*G6, 0) | I6: =IF(E6>0, H6*1, 0) | J6: =IF(E6>0, E6-I6, 0)
A7: FA-003 | H7: =IF(E7>0, E7*G7, 0) | I7: =IF(E7>0, H7*1, 0) | J7: =IF(E7>0, E7-I7, 0)
A8: FA-004 | H8: =IF(E8>0, E8*G8, 0) | I8: =IF(E8>0, H8*1, 0) | J8: =IF(E8>0, E8-I8, 0)
A9: FA-005 | H9: =IF(E9>0, E9*G9, 0) | I9: =IF(E9>0, H9*1, 0) | J9: =IF(E9>0, E9-I9, 0)
A10: FA-006 | H10: =IF(E10>0, E10*G10, 0) | I10: =IF(E10>0, H10*1, 0) | J10: =IF(E10>0, E10-I10, 0)
A11: FA-007 | H11: =IF(E11>0,E11*G11,0) | I11: =IF(E11>0,H11*1,0) | J11: =IF(E11>0,E11-I11,0)
A12: FA-008 | H12: =IF(E12>0,E12*G12,0) | I12: =IF(E12>0,H12*1,0) | J12: =IF(E12>0,E12-I12,0)
A13: FA-009 | H13: =IF(E13>0,E13*G13,0) | I13: =IF(E13>0,H13*1,0) | J13: =IF(E13>0,E13-I13,0)
A14: FA-010 | H14: =IF(E14>0,E14*G14,0) | I14: =IF(E14>0,H14*1,0) | J14: =IF(E14>0,E14-I14,0)
A15: FA-011 | H15: =IF(E15>0,E15*G15,0) | I15: =IF(E15>0,H15*1,0) | J15: =IF(E15>0,E15-I15,0)
A16: FA-012 | H16: =IF(E16>0,E16*G16,0) | I16: =IF(E16>0,H16*1,0) | J16: =IF(E16>0,E16-I16,0)
A17: FA-013 | H17: =IF(E17>0,E17*G17,0) | I17: =IF(E17>0,H17*1,0) | J17: =IF(E17>0,E17-I17,0)
A18: FA-014 | H18: =IF(E18>0,E18*G18,0) | I18: =IF(E18>0,H18*1,0) | J18: =IF(E18>0,E18-I18,0)
A19: FA-015 | H19: =IF(E19>0,E19*G19,0) | I19: =IF(E19>0,H19*1,0) | J19: =IF(E19>0,E19-I19,0)
A20: FA-016 | H20: =IF(E20>0,E20*G20,0) | I20: =IF(E20>0,H20*1,0) | J20: =IF(E20>0,E20-I20,0)
A21: FA-017 | H21: =IF(E21>0,E21*G21,0) | I21: =IF(E21>0,H21*1,0) | J21: =IF(E21>0,E21-I21,0)
A22: FA-018 | H22: =IF(E22>0,E22*G22,0) | I22: =IF(E22>0,H22*1,0) | J22: =IF(E22>0,E22-I22,0)
... A29: FA-025 | H29: =IF(E29>0,E29*G29,0) | I29: =IF(E29>0,H29*1,0) | J29: =IF(E29>0,E29-I29,0)
A30: TOTALS | E30: =SUM(E5:E29) | H30: =SUM(H5:H29) | I30: =SUM(I5:I29) | J30: =SUM(J5:J29)
A32: DEPRECIATION SUMMARY – feeds into Tax Engine (Step 3)
A33: Computers & Equipment (33.33%) | B33: =SUMIF(C5:C29,"Computers & Equipment",H5:H29)
A34: Motor Vehicles (20%) | B34: =SUMIF(C5:C29,"Motor Vehicles",H5:H29)
A35: Plant & Machinery (10%) | B35: =SUMIF(C5:C29,"Plant & Machinery",H5:H29)
A36: Industrial Buildings (4%) | B36: =SUMIF(C5:C29,"Industrial Buildings",H5:H29)
A37: TOTAL ANNUAL DEPRECIATION (NAD) | B37: =SUM(B33:B36)

Sheet VAT Ledger
A1: VAT LEDGER | Reconciliação do IVA | NamRA – Standard Rate 15%
A2: Output VAT = VAT charged on sales | Input VAT = VAT paid on purchases | Net VAT Payable = Output – Input
A3: SECTION A – OUTPUT VAT (VAT Charged on Sales / Revenue)
A4: # | B4: Description | C4: Invoice Date | D4: Gross Amount (NAD) | E4: VAT Rate | F4: VAT Amount (NAD) | G4: Net (Excl. VAT)
A5: 1 | E5: =Settings!$B$5 | F5: =IF(D5>0,D5*E5/(1+E5),0) | G5: =IF(D5>0,D5-F5,0)
A6: 2 | E6: =Settings!$B$5 | F6: =IF(D6>0,D6*E6/(1+E6),0) | G6: =IF(D6>0,D6-F6,0)
A7: 3 | E7: =Settings!$B$5 | F7: =IF(D7>0,D7*E7/(1+E7),0) | G7: =IF(D7>0,D7-F7,0)
A8: 4 | E8: =Settings!$B$5 | F8: =IF(D8>0,D8*E8/(1+E8),0) | G8: =IF(D8>0,D8-F8,0)
A9: 5 | E9: =Settings!$B$5 | F9: =IF(D9>0,D9*E9/(1+E9),0) | G9: =IF(D9>0,D9-F9,0)
A10: 6 | E10: =Settings!$B$5 | F10: =IF(D10>0,D10*E10/(1+E10),0) | G10: =IF(D10>0,D10-F10,0)
A11: 7 | E11: =Settings!$B$5 | F11: =IF(D11>0,D11*E11/(1+E11),0) | G11: =IF(D11>0,D11-F11,0)
A12: 8 | E12: =Settings!$B$5 | F12: =IF(D12>0,D12*E12/(1+E12),0) | G12: =IF(D12>0,D12-F12,0)
A13: 9 | E13: =Settings!$B$5 | F13: =IF(D13>0,D13*E13/(1+E13),0) | G13: =IF(D13>0,D13-F13,0)
A14: 10 | E14: =Settings!$B$5 | F14: =IF(D14>0,D14*E14/(1+E14),0) | G14: =IF(D14>0,D14-F14,0)
A15: 11 | E15: =Settings!$B$5 | F15: =IF(D15>0,D15*E15/(1+E15),0) | G15: =IF(D15>0,D15-F15,0)
A16: 12 | E16: =Settings!$B$5 | F16: =IF(D16>0,D16*E16/(1+E16),0) | G16: =IF(D16>0,D16-F16,0)
... A29: 25 | E29: =Settings!$B$5 | F29: =IF(D29>0,D29*E29/(1+E29),0) | G29: =IF(D29>0,D29-F29,0)
B30: TOTAL OUTPUT VAT | D30: =SUM(D5:D29) | F30: =SUM(F5:F29) | G30: =SUM(G5:G29)
A32: SECTION B – INPUT VAT (VAT Paid on Purchases / Expenses)
A33: # | B33: Description | C33: Invoice Date | D33: Gross Amount (NAD) | E33: VAT Rate | F33: VAT Amount (NAD) | G33: Net (Excl. VAT)
A34: 1 | E34: =Settings!$B$5 | F34: =IF(D34>0,D34*E34/(1+E34),0) | G34: =IF(D34>0,D34-F34,0)
A35: 2 | E35: =Settings!$B$5 | F35: =IF(D35>0,D35*E35/(1+E35),0) | G35: =IF(D35>0,D35-F35,0)
A36: 3 | E36: =Settings!$B$5 | F36: =IF(D36>0,D36*E36/(1+E36),0) | G36: =IF(D36>0,D36-F36,0)
A37: 4 | E37: =Settings!$B$5 | F37: =IF(D37>0,D37*E37/(1+E37),0) | G37: =IF(D37>0,D37-F37,0)
A38: 5 | E38: =Settings!$B$5 | F38: =IF(D38>0,D38*E38/(1+E38),0) | G38: =IF(D38>0,D38-F38,0)
A39: 6 | E39: =Settings!$B$5 | F39: =IF(D39>0,D39*E39/(1+E39),0) | G39: =IF(D39>0,D39-F39,0)
A40: 7 | E40: =Settings!$B$5 | F40: =IF(D40>0,D40*E40/(1+E40),0) | G40: =IF(D40>0,D40-F40,0)
A41: 8 | E41: =Settings!$B$5 | F41: =IF(D41>0,D41*E41/(1+E41),0) | G41: =IF(D41>0,D41-F41,0)
A42: 9 | E42: =Settings!$B$5 | F42: =IF(D42>0,D42*E42/(1+E42),0) | G42: =IF(D42>0,D42-F42,0)
A43: 10 | E43: =Settings!$B$5 | F43: =IF(D43>0,D43*E43/(1+E43),0) | G43: =IF(D43>0,D43-F43,0)
A44: 11 | E44: =Settings!$B$5 | F44: =IF(D44>0,D44*E44/(1+E44),0) | G44: =IF(D44>0,D44-F44,0)
A45: 12 | E45: =Settings!$B$5 | F45: =IF(D45>0,D45*E45/(1+E45),0) | G45: =IF(D45>0,D45-F45,0)
... A58: 25 | E58: =Settings!$B$5 | F58: =IF(D58>0,D58*E58/(1+E58),0) | G58: =IF(D58>0,D58-F58,0)
B59: TOTAL INPUT VAT | D59: =SUM(D34:D58) | F59: =SUM(F34:F58) | G59: =SUM(G34:G58)
A61: SECTION C – NET VAT RECONCILIATION & NamRA LIABILITY
A62: Total Output VAT (VAT on Sales) | F62: =F30
A63: Less: Total Input VAT (VAT on Purchases) | F63: =-F59
A64: NET VAT PAYABLE TO NamRA | F64: =F62+F63
A65: NamRA VAT Return Due: 25th of the month following the tax period | VAT Period: Monthly (if turnover > NAD 500,000) or Bi-monthly
A67: SECTION D – AUTO-SUMMARY FROM JOURNAL (cross-check)
...

Sheet Controls & Audit
A1: MODEL CONTROLS, AUDIT LOG & DATA VALIDATION GUIDE
A2: This sheet documents all manual inputs, version history, and data validation rules applied in the model.
A3: MODEL VERSION & METADATA
A4: Model Name | B4: Namibia Financial Model
A5: Version | B5: v7.0
A6: Prepared By | B6: ← Enter name
A7: Reviewed By | B7: ← Enter reviewer name
A8: Date Prepared | B8: ← Enter preparation date
A9: Reporting Period | B9: =Settings!B7
A10: Currency | B10: Namibian Dollar (NAD)
A11: Tax Authority | B11: NamRA – Namibia Revenue Agency
A12: Last Modified | B12: 11 June 2026
A13: Status | B13: DRAFT
A15: COLOUR CODING LEGEND
A16: Aa | B16: Blue text | C16: Hardcoded input – value entered manually by user
A17: Aa | B17: Black text | C17: Formula – auto-calculated, do not override
A18: Aa | B18: Green text | C18: Cross-sheet link – pulls from another tab
A19: Aa | B19: Red text | C19: External link – pulls from another workbook
A20: Aa | B20: Yellow background | C20: Key assumption requiring attention / review
A21: Aa | B21: Blue background | C21: Subtotal row
A22: Aa | B22: Navy background | C22: Grand total / primary KPI row
A24: MANUAL INPUT REGISTER – All hardcoded values in the model
A25: Sheet | B25: Cell | C25: Description | D25: Value | E25: Validation Rule | F25: Last Updated
A26: Settings | B26: B4 | C26: Corporate Tax Rate | D26: 30% | E26: 0% – 100%
A27: Settings | B27: B5 | C27: VAT Rate | D27: 15% | E27: 0% – 100%
A28: Settings | B28: B6 | C28: Annual Interest Rate | D28: 10% | E28: 0% – 100% | F28: Update when loan rate changes
A29: Journal | B29: E2:E21 | C29: Transaction Amounts | D29: Various | E29: Must be ≥ 0
A30: Tax Engine | B30: C7 | C30: Fines & Penalties Add-Back | D30: 0 | E30: Must be ≥ 0
A31: Tax Engine | B31: C8 | C31: 50% Entertainment Disallowance | D31: 0 | E31: Must be ≥ 0
A32: Tax Engine | B32: C9 | C32: Other Non-Deductible Items | D32: 0 | E32: Must be ≥ 0 | F32: Manual
A33: Tax Engine | B33: C14-17 | C33: Capital Allowances (Wear & Tear) | D33: 0 each | E33: Must be ≥ 0 | F33: Manual
A34: Balance Sheet | B34: C13 | C34: Prior Year Retained Earnings | D34: 0 | E34: Any value | F34: Manual
A35: Asset Register | B35: E5:E10 | C35: Asset Costs | D35: Various | E35: Must be > 0
A36: Asset Register | B36: G5:G10 | C36: NamRA Depreciation Rates | D36: Various | E36: Per NamRA schedule | F36: Fixed
A37: Cash Flow | B37: C31 | C37: Opening Cash Balance | D37: 0 | E37: Must be ≥ 0
A39: DATA VALIDATION RULES APPLIED IN THIS MODEL
A40: Tax Rates (Settings B4:B5) | B40: Decimal between 0 and 1. Input must be entered as decimal (e.g. 0.30 for 30%).
A41: Transaction Amounts (Journal col E) | B41: Decimal ≥ 0. Negative amounts are not permitted in the Amount column.
A42: Asset Costs (Asset Register col E) | B42: Decimal ≥ 0. Leave blank if asset not yet acquired.
A43: NamRA Rates (Asset Register col G) | B43: Decimal between 0 and 1. Refer to NamRA schedule: 0.3333, 0.20, 0.10, 0.04.
...

Sheet AFS - Cover
A1: ANNUAL FINANCIAL STATEMENTS
A2: =Settings!B8
A3: ="for the period ended "&Settings!B7
A5: GENERAL INFORMATION
A6: Entity name | B6: =Settings!B8
A7: Reporting period | B7: =Settings!B7
A8: Country of incorporation | B8: Namibia
A9: Functional & presentation currency | B9: Namibian Dollar (NAD)
A10: Tax authority | B10: Namibia Revenue Agency (NamRA)
A11: Corporate income tax rate | B11: =Settings!B4
A12: Basis of accounting | B12: Historical cost; accrual basis; going concern
A14: CONTENTS OF THE ANNUAL FINANCIAL STATEMENTS
A15: Statement of Profit or Loss and Other Comprehensive Income | B15: see tab: AFS - Income
A16: Statement of Financial Position | B16: see tab: AFS - Position
A17: Statement of Changes in Equity | B17: see tab: AFS - Equity
A18: Statement of Cash Flows | B18: see tab: AFS - Cash Flows
A19: Notes to the Annual Financial Statements | B19: see tab: AFS - Notes
A21: APPROVAL OF THE ANNUAL FINANCIAL STATEMENTS
A22: The annual financial statements set out in these statements, which have been prepared on the going-concern basis, were approved by the directors and are signed on their behalf by:
A25: Director: ______________________________ | B25: Date: ____________________
A27: Director: ______________________________ | B27: Date: ____________________
A29: Directors are responsible for the preparation and fair presentation of these financial statements and for maintaining adequate accounting records and internal controls.

Sheet AFS - Income
A1: =Settings!B8
A2: Statement of Profit or Loss and Other Comprehensive Income
A3: ="for the period ended "&Settings!B7
B5: Note | C5: Current period (N$) | D5: Prior period (N$)
A6: Revenue | B6: 3 | C6: ='Income Statement'!C7 | D6: ='Income Statement'!E7
A7: Cost of sales | C7: =-'Income Statement'!C11 | D7: =-'Income Statement'!E11
A8: Gross profit | C8: ='Income Statement'!C12 | D8: ='Income Statement'!E12
A9: Other operating expenses | B9: 4 | C9: =-'Income Statement'!C24 | D9: =-'Income Statement'!E24
A10: Operating profit | C10: ='Income Statement'!C25 | D10: ='Income Statement'!E25
A11: Finance costs | B11: 5 | C11: =-'Income Statement'!C27 | D11: =-'Income Statement'!E27
A12: Profit before taxation | C12: ='Income Statement'!C28 | D12: ='Income Statement'!E28
A13: Income tax expense | B13: 6 | C13: =-'Tax Engine'!C30 | D13: =-'Income Statement'!E29
A14: Profit for the period | C14: ='Income Statement'!C31 | D14: ='Income Statement'!E31
A15: Other comprehensive income | C15: 0 | D15: 0
A16: Total comprehensive income for the period | C16: ='Income Statement'!C31 | D16: ='Income Statement'!E31
A18: All amounts in Namibian Dollars (N$). Figures flow automatically from the Income Statement and Tax Engine.

Sheet AFS - Position
A1: =Settings!B8
A2: Statement of Financial Position
A3: ="for the period ended "&Settings!B7
B5: Note | C5: Current period (N$) | D5: Prior period (N$)
A6: ASSETS
A7: Non-current assets
A8: Property, plant and equipment | B8: 7 | C8: ='Balance Sheet'!C14 | D8: ='Prior Year'!B8+'Prior Year'!B9
A9: Total non-current assets | C9: ='Balance Sheet'!C14 | D9: ='Prior Year'!B8+'Prior Year'!B9
A10: Current assets
A11: Inventories | B11: 8 | C11: ='Balance Sheet'!C8 | D11: ='Prior Year'!B6
A12: Trade and other receivables | B12: 9 | C12: ='Balance Sheet'!C7+'Balance Sheet'!C9 | D12: ='Prior Year'!B5+'Prior Year'!B7
A13: Cash and cash equivalents | B13: 10 | C13: ='Balance Sheet'!C6 | D13: ='Prior Year'!B4
A14: Total current assets | C14: ='Balance Sheet'!C10 | D14: ='Prior Year'!B4+'Prior Year'!B5+'Prior Year'!B6+'Prior Year'!B7
A15: TOTAL ASSETS | C15: ='Balance Sheet'!C15 | D15: ='Prior Year'!B17
A16: EQUITY AND LIABILITIES
A17: Equity
A18: Share capital | B18: 11 | C18: ='Balance Sheet'!C30 | D18: ='Prior Year'!B15
A19: Retained earnings | C19: ='Balance Sheet'!C31+'Balance Sheet'!C32+'Balance Sheet'!C33 | D19: ='Prior Year'!B16
A20: Total equity | C20: ='Balance Sheet'!C34 | D20: ='Prior Year'!B19
A21: Non-current liabilities
A22: Loans and borrowings | B22: 12 | C22: ='Balance Sheet'!C26 | D22: ='Prior Year'!B14
A23: Total non-current liabilities | C23: ='Balance Sheet'!C26 | D23: ='Prior Year'!B14
A24: Current liabilities
A25: Trade and other payables | B25: 13 | C25: ='Balance Sheet'!C19+'Balance Sheet'!C20+'Balance Sheet'!C22 | D25: ='Prior Year'!B10+'Prior Year'!B11+'Prior Year'!B13
A26: Current tax payable | B26: 14 | C26: ='Balance Sheet'!C21 | D26: ='Prior Year'!B12
A27: Total current liabilities | C27: ='Balance Sheet'!C23 | D27: ='Prior Year'!B10+'Prior Year'!B11+'Prior Year'!B12+'Prior Year'!B13
A28: Total liabilities | C28: ='Balance Sheet'!C27 | D28: ='Prior Year'!B18
A29: TOTAL EQUITY AND LIABILITIES | C29: ='Balance Sheet'!C35 | D29: ='Prior Year'!B18+'Prior Year'!B19
A30: Balance check (Assets − Equity − Liabilities, must be 0): | C30: ='Balance Sheet'!C15-'Balance Sheet'!C35
A31: Prior-period column populates from the Prior Year sheet.

Sheet AFS - Equity
A1: =Settings!B8
A2: Statement of Changes in Equity
A3: ="for the period ended "&Settings!B7
B5: Share capital (N$) | C5: Retained earnings (N$) | D5: Total equity (N$)
A6: Balance at beginning of the period | B6: ='Prior Year'!B15 | C6: ='Prior Year'!B16 | D6: =B6+C6
A7: Profit for the period | B7: 0 | C7: ='Income Statement'!C31 | D7: =B7+C7
A8: Dividends declared | B8: 0 | C8: =-'Income Statement'!C30 | D8: =B8+C8
A9: Shares issued during the period | B9: ='Cash Flow'!C25 | C9: 0 | D9: =B9+C9
A10: Balance at end of the period | B10: =SUM(B6:B9) | C10: =SUM(C6:C9) | D10: =SUM(D6:D9)
A12: Cross-check: closing total equity vs Balance Sheet: | D12: =D10-'Balance Sheet'!C34

Sheet AFS - Cash Flows
A1: =Settings!B8
A2: Statement of Cash Flows
A3: ="for the period ended "&Settings!B7
B5: Note | C5: N$
A6: CASH FLOWS FROM OPERATING ACTIVITIES
A7: Profit for the period | C7: ='Cash Flow'!C4
A8: Adjustment for depreciation | B8: 7 | C8: ='Cash Flow'!C6
A9: Adjustment for amortisation | C9: ='Cash Flow'!C7
A10: Working capital movements (incl. tax payable) | C10: =SUM('Cash Flow'!C9:C15)
A11: Net cash from operating activities | C11: ='Cash Flow'!C16
A12: CASH FLOWS FROM INVESTING ACTIVITIES
A13: Purchase of property, plant and equipment | C13: ='Cash Flow'!C19
A14: Proceeds from disposal of assets | C14: ='Cash Flow'!C20
A15: Purchase of investments | C15: ='Cash Flow'!C21
A16: Net cash from investing activities | C16: ='Cash Flow'!C22
A17: CASH FLOWS FROM FINANCING ACTIVITIES
A18: Proceeds from share capital issuance | B18: 11 | C18: ='Cash Flow'!C25
A19: Repayment of loans | B19: 12 | C19: ='Cash Flow'!C26
A20: Dividends paid | C20: ='Cash Flow'!C27
A21: Proceeds from new borrowings | B21: 12 | C21: ='Cash Flow'!C28
A22: Net cash from financing activities | C22: ='Cash Flow'!C29
A23: Net increase / (decrease) in cash | C23: ='Cash Flow'!C33
A24: Cash and cash equivalents at beginning of period | C24: ='Cash Flow'!C32
A25: Cash and cash equivalents at end of period | B25: 10 | C25: ='Cash Flow'!C34
A26: Cross-check vs cash in Statement of Financial Position: | C26: ='Cash Flow'!C34-'Balance Sheet'!C6

Sheet AFS - Notes
A1: =Settings!B8
A2: Notes to the Annual Financial Statements
A3: ="for the period ended "&Settings!B7
A5: 1. General information
A6: The entity is a company incorporated and domiciled in Namibia. These financial statements present the results of operations and the financial position for the reporting period indicated above. The functional and presentation currency is the Namibian Dollar (N$). The company is registered for tax with the Namibia Revenue Agency (NamRA).
A8: 2. Basis of preparation and significant accounting policies
A9: Basis of preparation: The financial statements are prepared on the historical-cost basis, under the accrual concept and on the assumption that the company is a going concern.
A10: Revenue: Revenue is measured at the fair value of consideration received or receivable, net of value added tax (VAT), and is recognised when the related goods or services are delivered.
A11: Property, plant and equipment: Stated at cost less accumulated depreciation. For tax purposes, wear-and-tear (capital) allowances are claimed per the NamRA schedule (computers 33.33%, vehicles 20%, plant 10%, industrial buildings 4%).
A12: Taxation: Income tax is provided at the corporate rate on taxable income, computed by adjusting accounting profit for non-deductible items and capital allowances. Provisional tax is paid in two instalments (P1 40% in August; P2 balance in February).
A13: Value added tax (VAT): Recognised at the standard rate. Output VAT on sales less input VAT on purchases is payable to NamRA.
A15: 3. Revenue
B16: Sales revenue | C16: ='Income Statement'!C4
B17: Service revenue | C17: ='Income Statement'!C5
B18: Other income | C18: ='Income Statement'!C6
B19: Total revenue | C19: ='Income Statement'!C7
A21: 4. Operating profit / other operating expenses
B22: Salaries & wages | C22: ='Income Statement'!C14
B23: Rent expense | C23: ='Income Statement'!C15
B24: Utilities | C24: ='Income Statement'!C16
B25: Marketing & advertising | C25: ='Income Statement'!C17
B26: Depreciation | C26: ='Income Statement'!C18
B27: Travel & entertainment | C27: ='Income Statement'!C19
B28: Professional fees | C28: ='Income Statement'!C20
B29: Bank charges | C29: ='Income Statement'!C21
B30: Fines & penalties | C30: ='Income Statement'!C22
B31: Entertainment (50% non-deductible) | C31: ='Income Statement'!C23
B32: Total operating expenses | C32: ='Income Statement'!C24
A34: 5. Finance costs
B35: Interest on loans payable | C35: ='Income Statement'!C27 | D35: Loans balance × interest rate (Settings)
B36: Annual interest rate applied | C36: =Settings!B6
A38: 6. Income tax expense
B39: Accounting profit before tax (EBT) | C39: ='Tax Engine'!C4
B40: Add: non-deductible expenses | C40: ='Tax Engine'!C10
B41: Less: capital allowances | C41: =-'Tax Engine'!C18
B42: Taxable income | C42: ='Tax Engine'!C25
B43: Corporate tax rate | C43: =Settings!B4
B44: Income tax expense | C44: ='Tax Engine'!C30
B45: – 1st provisional payment (P1, Aug) | C45: ='Tax Engine'!C34
B46: – 2nd provisional payment (P2, Feb) | C46: ='Tax Engine'!C35
...
